Workbook

Sheet Jun.26
A1: YEAR | B1: MONTH | C1: CUSTOMER | D1: GROUP | E1: M/C NO. | F1: PRODUCT NAME | G1: PLAN OUTPUT (pcs.) | H1: ACTUAL OUTPUT (pcs.) | I1: PLAN AMOUNT (THB) | J1: ACTUAL AMOUNT (THB) | K1: PD Output ratio | L1: Status
A2: 2026 | B2: JUN | C2: WDC | D2: HDD | E2: =_xlfn.XLOOKUP(F2,'Daily WDC'!B:B,'Daily WDC'!C:C) -> H2(40ton) | F2: Latch Esprit M5 | G2: =SUMIFS('Daily WDC'!$AJ$9:$AJ$582,'Daily WDC'!$A$9:$A$582,Jun.26!E2,'Daily WDC'!$B$9:$B$582,Jun.26!F2) -> 0 | H2: =SUMIFS('Daily WDC'!$AK$9:$AK$582,'Daily WDC'!$A$9:$A$582,Jun.26!E2,'Daily WDC'!$B$9:$B$582,Jun.26!F2) -> 0 | I2: =SUMIFS('Daily WDC'!$AL$9:$AL$582,'Daily WDC'!$A$9:$A$582,Jun.26!E2,'Daily WDC'!$B$9:$B$582,Jun.26!F2) -> 0 | J2: =SUMIFS('Daily WDC'!$AM$9:$AM$582,'Daily WDC'!$A$9:$A$582,Jun.26!E2,'Daily WDC'!$B$9:$B$582,Jun.26!F2) -> 0 | K2: =H2/G2 -> #DIV/0! | L2: =IF(K2>1,"Achieved","Unachieved") -> #DIV/0!
A3: 2026 | B3: JUN | C3: WDC | D3: HDD | E3: =_xlfn.XLOOKUP(F3,'Daily WDC'!B:B,'Daily WDC'!C:C) -> H2(40ton) | F3: Latch Spyglass M1 | G3: =SUMIFS('Daily WDC'!$AJ$9:$AJ$582,'Daily WDC'!$A$9:$A$582,Jun.26!E3,'Daily WDC'!$B$9:$B$582,Jun.26!F3) -> 300000 | H3: =SUMIFS('Daily WDC'!$AK$9:$AK$582,'Daily WDC'!$A$9:$A$582,Jun.26!E3,'Daily WDC'!$B$9:$B$582,Jun.26!F3) -> 38000 | I3: =SUMIFS('Daily WDC'!$AL$9:$AL$582,'Daily WDC'!$A$9:$A$582,Jun.26!E3,'Daily WDC'!$B$9:$B$582,Jun.26!F3) -> 357537 | J3: =SUMIFS('Daily WDC'!$AM$9:$AM$582,'Daily WDC'!$A$9:$A$582,Jun.26!E3,'Daily WDC'!$B$9:$B$582,Jun.26!F3) -> 45288.02 | K3: =H3/G2 -> #DIV/0! | L3: =IF(K3>1,"Achieved","Unachieved") -> #DIV/0!
A4: 2026 | B4: JUN | C4: WDC | D4: HDD | E4: =_xlfn.XLOOKUP(F4,'Daily WDC'!B:B,'Daily WDC'!C:C) -> H3(50ton) | F4: Air Spoiler Sydney-E M2 | G4: =SUMIFS('Daily WDC'!$AJ$9:$AJ$582,'Daily WDC'!$A$9:$A$582,Jun.26!E4,'Daily WDC'!$B$9:$B$582,Jun.26!F4) -> 300000 | H4: =SUMIFS('Daily WDC'!$AK$9:$AK$582,'Daily WDC'!$A$9:$A$582,Jun.26!E4,'Daily WDC'!$B$9:$B$582,Jun.26!F4) -> 241584 | I4: =SUMIFS('Daily WDC'!$AL$9:$AL$582,'Daily WDC'!$A$9:$A$582,Jun.26!E4,'Daily WDC'!$B$9:$B$582,Jun.26!F4) -> 1542018 | J4: =SUMIFS('Daily WDC'!$AM$9:$AM$582,'Daily WDC'!$A$9:$A$582,Jun.26!E4,'Daily WDC'!$B$9:$B$582,Jun.26!F4) -> 1241756.3 | K4: =H4/G4 -> 0.80528 | L4: =IF(K4>1,"Achieved","Unachieved") -> Unachieved
A5: 2026 | B5: JUN | C5: WDC | D5: HDD | E5: =_xlfn.XLOOKUP(F5,'Daily WDC'!B:B,'Daily WDC'!C:C) -> H3(50ton) | F5: Air Spoiler Paris-C M3 | G5: =SUMIFS('Daily WDC'!$AJ$9:$AJ$582,'Daily WDC'!$A$9:$A$582,Jun.26!E5,'Daily WDC'!$B$9:$B$582,Jun.26!F5) -> 0 | H5: =SUMIFS('Daily WDC'!$AK$9:$AK$582,'Daily WDC'!$A$9:$A$582,Jun.26!E5,'Daily WDC'!$B$9:$B$582,Jun.26!F5) -> 0 | I5: =SUMIFS('Daily WDC'!$AL$9:$AL$582,'Daily WDC'!$A$9:$A$582,Jun.26!E5,'Daily WDC'!$B$9:$B$582,Jun.26!F5) -> 0 | J5: =SUMIFS('Daily WDC'!$AM$9:$AM$582,'Daily WDC'!$A$9:$A$582,Jun.26!E5,'Daily WDC'!$B$9:$B$582,Jun.26!F5) -> 0 | K5: =H5/G5 -> #DIV/0! | L5: =IF(K5>1,"Achieved","Unachieved") -> #DIV/0!
A6: 2026 | B6: JUN | C6: WDC | D6: HDD | E6: =_xlfn.XLOOKUP(F6,'Daily WDC'!B:B,'Daily WDC'!C:C) -> H5(50ton) | F6: Air Spoiler Sydney-E M1 | G6: =SUMIFS('Daily WDC'!$AJ$9:$AJ$582,'Daily WDC'!$A$9:$A$582,Jun.26!E6,'Daily WDC'!$B$9:$B$582,Jun.26!F6) -> 348000 | H6: =SUMIFS('Daily WDC'!$AK$9:$AK$582,'Daily WDC'!$A$9:$A$582,Jun.26!E6,'Daily WDC'!$B$9:$B$582,Jun.26!F6) -> 127680 | I6: =SUMIFS('Daily WDC'!$AL$9:$AL$582,'Daily WDC'!$A$9:$A$582,Jun.26!E6,'Daily WDC'!$B$9:$B$582,Jun.26!F6) -> 1788740.9 | J6: =SUMIFS('Daily WDC'!$AM$9:$AM$582,'Daily WDC'!$A$9:$A$582,Jun.26!E6,'Daily WDC'!$B$9:$B$582,Jun.26!F6) -> 656282.86 | K6: =H6/G6 -> 0.36689655 | L6: =IF(K6>1,"Achieved","Unachieved") -> Unachieved
A7: 2026 | B7: JUN | C7: WDC | D7: HDD | E7: =_xlfn.XLOOKUP(F7,'Daily WDC'!B:B,'Daily WDC'!C:C) -> H6(50ton) | F7: Air Spoiler Sydney-E M3 | G7: =SUMIFS('Daily WDC'!$AJ$9:$AJ$582,'Daily WDC'!$A$9:$A$582,Jun.26!E7,'Daily WDC'!$B$9:$B$582,Jun.26!F7) -> 284000 | H7: =SUMIFS('Daily WDC'!$AK$9:$AK$582,'Daily WDC'!$A$9:$A$582,Jun.26!E7,'Daily WDC'!$B$9:$B$582,Jun.26!F7) -> 264264 | I7: =SUMIFS('Daily WDC'!$AL$9:$AL$582,'Daily WDC'!$A$9:$A$582,Jun.26!E7,'Daily WDC'!$B$9:$B$582,Jun.26!F7) -> 1459777 | J7: =SUMIFS('Daily WDC'!$AM$9:$AM$582,'Daily WDC'!$A$9:$A$582,Jun.26!E7,'Daily WDC'!$B$9:$B$582,Jun.26!F7) -> 1358332.8 | K7: =H7/G7 -> 0.93050704 | L7: =IF(K7>1,"Achieved","Unachieved") -> Unachieved
A8: 2026 | B8: JUN | C8: WDC | D8: HDD | E8: =_xlfn.XLOOKUP(F8,'Daily WDC'!B:B,'Daily WDC'!C:C) -> H6(50ton) | F8: Air Spoiler London-D M3 | G8: =SUMIFS('Daily WDC'!$AJ$9:$AJ$582,'Daily WDC'!$A$9:$A$582,Jun.26!E8,'Daily WDC'!$B$9:$B$582,Jun.26!F8) -> 0 | H8: =SUMIFS('Daily WDC'!$AK$9:$AK$582,'Daily WDC'!$A$9:$A$582,Jun.26!E8,'Daily WDC'!$B$9:$B$582,Jun.26!F8) -> 0 | I8: =SUMIFS('Daily WDC'!$AL$9:$AL$582,'Daily WDC'!$A$9:$A$582,Jun.26!E8,'Daily WDC'!$B$9:$B$582,Jun.26!F8) -> 0 | J8: =SUMIFS('Daily WDC'!$AM$9:$AM$582,'Daily WDC'!$A$9:$A$582,Jun.26!E8,'Daily WDC'!$B$9:$B$582,Jun.26!F8) -> 0 | K8: =H8/G8 -> #DIV/0! | L8: =IF(K8>1,"Achieved","Unachieved") -> #DIV/0!
A9: 2026 | B9: JUN | C9: WDC | D9: HDD | E9: =_xlfn.XLOOKUP(F9,'Daily WDC'!B:B,'Daily WDC'!C:C) -> H7(50ton) | F9: Air Spoiler London-D M1 | G9: =SUMIFS('Daily WDC'!$AJ$9:$AJ$582,'Daily WDC'!$A$9:$A$582,Jun.26!E9,'Daily WDC'!$B$9:$B$582,Jun.26!F9) -> 270000 | H9: =SUMIFS('Daily WDC'!$AK$9:$AK$582,'Daily WDC'!$A$9:$A$582,Jun.26!E9,'Daily WDC'!$B$9:$B$582,Jun.26!F9) -> 215208 | I9: =SUMIFS('Daily WDC'!$AL$9:$AL$582,'Daily WDC'!$A$9:$A$582,Jun.26!E9,'Daily WDC'!$B$9:$B$582,Jun.26!F9) -> 1110982.5 | J9: =SUMIFS('Daily WDC'!$AM$9:$AM$582,'Daily WDC'!$A$9:$A$582,Jun.26!E9,'Daily WDC'!$B$9:$B$582,Jun.26!F9) -> 885527.12 | K9: =H9/G9 -> 0.79706667 | L9: =IF(K9>1,"Achieved","Unachieved") -> Unachieved
A10: 2026 | B10: JUN | C10: WDC | D10: HDD | E10: =_xlfn.XLOOKUP(F10,'Daily WDC'!B:B,'Daily WDC'!C:C) -> H8(50ton) | F10: Air Spoiler Vela-A M1 | G10: =SUMIFS('Daily WDC'!$AJ$9:$AJ$582,'Daily WDC'!$A$9:$A$582,Jun.26!E10,'Daily WDC'!$B$9:$B$582,Jun.26!F10) -> 240000 | H10: =SUMIFS('Daily WDC'!$AK$9:$AK$582,'Daily WDC'!$A$9:$A$582,Jun.26!E10,'Daily WDC'!$B$9:$B$582,Jun.26!F10) -> 182400 | I10: =SUMIFS('Daily WDC'!$AL$9:$AL$582,'Daily WDC'!$A$9:$A$582,Jun.26!E10,'Daily WDC'!$B$9:$B$582,Jun.26!F10) -> 1403613.6 | J10: =SUMIFS('Daily WDC'!$AM$9:$AM$582,'Daily WDC'!$A$9:$A$582,Jun.26!E10,'Daily WDC'!$B$9:$B$582,Jun.26!F10) -> 1066746.3 | K10: =H10/G10 -> 0.76 | L10: =IF(K10>1,"Achieved","Unachieved") -> Unachieved
A11: 2026 | B11: JUN | C11: WDC | D11: HDD | E11: =_xlfn.XLOOKUP(F11,'Daily WDC'!B:B,'Daily WDC'!C:C) -> H9(50ton) | F11: Air Spoiler Vela-A M2 | G11: =SUMIFS('Daily WDC'!$AJ$9:$AJ$582,'Daily WDC'!$A$9:$A$582,Jun.26!E11,'Daily WDC'!$B$9:$B$582,Jun.26!F11) -> 260000 | H11: =SUMIFS('Daily WDC'!$AK$9:$AK$582,'Daily WDC'!$A$9:$A$582,Jun.26!E11,'Daily WDC'!$B$9:$B$582,Jun.26!F11) -> 300000 | I11: =SUMIFS('Daily WDC'!$AL$9:$AL$582,'Daily WDC'!$A$9:$A$582,Jun.26!E11,'Daily WDC'!$B$9:$B$582,Jun.26!F11) -> 1520581.4 | J11: =SUMIFS('Daily WDC'!$AM$9:$AM$582,'Daily WDC'!$A$9:$A$582,Jun.26!E11,'Daily WDC'!$B$9:$B$582,Jun.26!F11) -> 1754517 | K11: =H11/G11 -> 1.1538462 | L11: =IF(K11>1,"Achieved","Unachieved") -> Achieved
A12: 2026 | B12: JUN | C12: WDC | D12: HDD | E12: =_xlfn.XLOOKUP(F12,'Daily WDC'!B:B,'Daily WDC'!C:C) -> H9(50ton) | F12: Air Spoiler Vela-AP M1 | G12: =SUMIFS('Daily WDC'!$AJ$9:$AJ$582,'Daily WDC'!$A$9:$A$582,Jun.26!E12,'Daily WDC'!$B$9:$B$582,Jun.26!F12) -> 0 | H12: =SUMIFS('Daily WDC'!$AK$9:$AK$582,'Daily WDC'!$A$9:$A$582,Jun.26!E12,'Daily WDC'!$B$9:$B$582,Jun.26!F12) -> 0 | I12: =SUMIFS('Daily WDC'!$AL$9:$AL$582,'Daily WDC'!$A$9:$A$582,Jun.26!E12,'Daily WDC'!$B$9:$B$582,Jun.26!F12) -> 0 | J12: =SUMIFS('Daily WDC'!$AM$9:$AM$582,'Daily WDC'!$A$9:$A$582,Jun.26!E12,'Daily WDC'!$B$9:$B$582,Jun.26!F12) -> 0 | K12: =H12/G12 -> #DIV/0! | L12: =IF(K12>1,"Achieved","Unachieved") -> #DIV/0!
A13: 2026 | B13: JUN | C13: WDC | D13: HDD | E13: =_xlfn.XLOOKUP(F13,'Daily WDC'!B:B,'Daily WDC'!C:C) -> H9(50ton) | F13: Air Spoiler Vela-AP M2 | G13: =SUMIFS('Daily WDC'!$AJ$9:$AJ$582,'Daily WDC'!$A$9:$A$582,Jun.26!E13,'Daily WDC'!$B$9:$B$582,Jun.26!F13) -> 0 | H13: =SUMIFS('Daily WDC'!$AK$9:$AK$582,'Daily WDC'!$A$9:$A$582,Jun.26!E13,'Daily WDC'!$B$9:$B$582,Jun.26!F13) -> 0 | I13: =SUMIFS('Daily WDC'!$AL$9:$AL$582,'Daily WDC'!$A$9:$A$582,Jun.26!E13,'Daily WDC'!$B$9:$B$582,Jun.26!F13) -> 0 | J13: =SUMIFS('Daily WDC'!$AM$9:$AM$582,'Daily WDC'!$A$9:$A$582,Jun.26!E13,'Daily WDC'!$B$9:$B$582,Jun.26!F13) -> 0 | K13: =H13/G13 -> #DIV/0! | L13: =IF(K13>1,"Achieved","Unachieved") -> #DIV/0!
A14: 2026 | B14: JUN | C14: WDC | D14: HDD | E14: =_xlfn.XLOOKUP(F14,'Daily WDC'!B:B,'Daily WDC'!C:C) -> H10(50ton) | F14: Air Spoiler Vela-AX M1 | G14: =SUMIFS('Daily WDC'!$AJ$9:$AJ$582,'Daily WDC'!$A$9:$A$582,Jun.26!E14,'Daily WDC'!$B$9:$B$582,Jun.26!F14) -> 120000 | H14: =SUMIFS('Daily WDC'!$AK$9:$AK$582,'Daily WDC'!$A$9:$A$582,Jun.26!E14,'Daily WDC'!$B$9:$B$582,Jun.26!F14) -> 102144 | I14: =SUMIFS('Daily WDC'!$AL$9:$AL$582,'Daily WDC'!$A$9:$A$582,Jun.26!E14,'Daily WDC'!$B$9:$B$582,Jun.26!F14) -> 311809.2 | J14: =SUMIFS('Daily WDC'!$AM$9:$AM$582,'Daily WDC'!$A$9:$A$582,Jun.26!E14,'Daily WDC'!$B$9:$B$582,Jun.26!F14) -> 265411.99 | K14: =H14/G14 -> 0.8512 | L14: =IF(K14>1,"Achieved","Unachieved") -> Unachieved
A15: 2026 | B15: JUN | C15: WDC | D15: HDD | E15: =_xlfn.XLOOKUP(F15,'Daily WDC'!B:B,'Daily WDC'!C:C) -> H10(50ton) | F15: Air Spoiler Venice M2 | G15: =SUMIFS('Daily WDC'!$AJ$9:$AJ$582,'Daily WDC'!$A$9:$A$582,Jun.26!E15,'Daily WDC'!$B$9:$B$582,Jun.26!F15) -> 0 | H15: =SUMIFS('Daily WDC'!$AK$9:$AK$582,'Daily WDC'!$A$9:$A$582,Jun.26!E15,'Daily WDC'!$B$9:$B$582,Jun.26!F15) -> 0 | I15: =SUMIFS('Daily WDC'!$AL$9:$AL$582,'Daily WDC'!$A$9:$A$582,Jun.26!E15,'Daily WDC'!$B$9:$B$582,Jun.26!F15) -> 0 | J15: =SUMIFS('Daily WDC'!$AM$9:$AM$582,'Daily WDC'!$A$9:$A$582,Jun.26!E15,'Daily WDC'!$B$9:$B$582,Jun.26!F15) -> 0 | K15: =H15/G15 -> #DIV/0! | L15: =IF(K15>1,"Achieved","Unachieved") -> #DIV/0!
... A20: 2026 | B20: JUN | C20: WDC | D20: HDD | E20: =_xlfn.XLOOKUP(F20,'Daily WDC'!B:B,'Daily WDC'!C:C) -> H22(50ton) | F20: Air Spoiler Sydney-E M4 | G20: =SUMIFS('Daily WDC'!$AJ$9:$AJ$582,'Daily WDC'!$A$9:$A$582,Jun.26!E20,'Daily WDC'!$B$9:$B$582,Jun.26!F20) -> 148000 | H20: =SUMIFS('Daily WDC'!$AK$9:$AK$582,'Daily WDC'!$A$9:$A$582,Jun.26!E20,'Daily WDC'!$B$9:$B$582,Jun.26!F20) -> 199920 | I20: =SUMIFS('Daily WDC'!$AL$9:$AL$582,'Daily WDC'!$A$9:$A$582,Jun.26!E20,'Daily WDC'!$B$9:$B$582,Jun.26!F20) -> 760728.88 | J20: =SUMIFS('Daily WDC'!$AM$9:$AM$582,'Daily WDC'!$A$9:$A$582,Jun.26!E20,'Daily WDC'!$B$9:$B$582,Jun.26!F20) -> 1027600.8 | K20: =H20/G20 -> 1.3508108 | L20: =IF(K20>1,"Achieved","Unachieved") -> Achieved
A21: 2026 | B21: JUN | C21: NET | D21: HDD | E21: =_xlfn.XLOOKUP(F21,'Daily Nidec'!B:B,'Daily Nidec'!C:C) -> H12(50ton) | F21: Filter Case Test TYD M2 | G21: =SUMIFS('Daily Nidec'!$AJ$8:$AJ$35,'Daily Nidec'!$A$8:$A$35,Jun.26!E21,'Daily Nidec'!$B$8:$B$35,Jun.26!F21) -> 19000 | H21: =SUMIFS('Daily Nidec'!$AK$8:$AK$35,'Daily Nidec'!$A$8:$A$35,Jun.26!E21,'Daily Nidec'!$B$8:$B$35,Jun.26!F21) -> 19040 | I21: =SUMIFS('Daily Nidec'!$AL$8:$AL$35,'Daily Nidec'!$A$8:$A$35,Jun.26!E21,'Daily Nidec'!$B$8:$B$35,Jun.26!F21) -> 73075.14 | J21: =SUMIFS('Daily Nidec'!$AM$8:$AM$35,'Daily Nidec'!$A$8:$A$35,Jun.26!E21,'Daily Nidec'!$B$8:$B$35,Jun.26!F21) -> 73228.982 | K21: =H21/G21 -> 1.0021053 | L21: =IF(K21>1,"Achieved","Unachieved") -> Achieved
A22: 2026 | B22: JUN | C22: SEAGATE | D22: HDD | E22: =_xlfn.XLOOKUP(F22,'Daily Seagate'!B:B,'Daily Seagate'!C:C) -> H17(50ton) | F22: TRAY,PLASTIC,SLIDER,WASH,DPEMTO | G22: =SUMIFS('Daily Seagate'!$AJ$9:$AJ$22,'Daily Seagate'!$A$9:$A$22,Jun.26!E22,'Daily Seagate'!$B$9:$B$22,Jun.26!F22) -> 0 | H22: =SUMIFS('Daily Seagate'!$AK$9:$AK$22,'Daily Seagate'!$A$9:$A$22,Jun.26!E22,'Daily Seagate'!$B$9:$B$22,Jun.26!F22) -> 0 | I22: =SUMIFS('Daily Seagate'!$AL$9:$AL$22,'Daily Seagate'!$A$9:$A$22,Jun.26!E22,'Daily Seagate'!$B$9:$B$22,Jun.26!F22) -> 0 | J22: =SUMIFS('Daily Seagate'!$AM$9:$AM$22,'Daily Seagate'!$A$9:$A$22,Jun.26!E22,'Daily Seagate'!$B$9:$B$22,Jun.26!F22) -> 0 | K22: =H22/G22 -> #DIV/0! | L22: =IF(K22>1,"Achieved","Unachieved") -> #DIV/0!
A23: 2026 | B23: JUN | C23: BIT | D23: HDD | E23: =_xlfn.XLOOKUP(F23,'Daily Belton'!B:B,'Daily Belton'!C:C) -> H19(110ton) | F23: Flex Bracket Sydney-F M1 | G23: =SUMIFS('Daily Belton'!$AJ$9:$AJ$64,'Daily Belton'!$A$9:$A$64,Jun.26!E23,'Daily Belton'!$B$9:$B$64,Jun.26!F23) -> 600000 | H23: =SUMIFS('Daily Belton'!$AK$9:$AK$64,'Daily Belton'!$A$9:$A$64,Jun.26!E23,'Daily Belton'!$B$9:$B$64,Jun.26!F23) -> 612900 | I23: =SUMIFS('Daily Belton'!$AL$9:$AL$64,'Daily Belton'!$A$9:$A$64,Jun.26!E23,'Daily Belton'!$B$9:$B$64,Jun.26!F23) -> 2069460 | J23: =SUMIFS('Daily Belton'!$AM$9:$AM$64,'Daily Belton'!$A$9:$A$64,Jun.26!E23,'Daily Belton'!$B$9:$B$64,Jun.26!F23) -> 2113953.4 | K23: =H23/G23 -> 1.0215 | L23: =IF(K23>1,"Achieved","Unachieved") -> Achieved
A24: 2026 | B24: JUN | C24: BIT | D24: HDD | E24: =_xlfn.XLOOKUP(F24,'Daily Belton'!B:B,'Daily Belton'!C:C) -> H18(110ton) | F24: Flex Bracket Sydney-E M2 | G24: =SUMIFS('Daily Belton'!$AJ$9:$AJ$64,'Daily Belton'!$A$9:$A$64,Jun.26!E24,'Daily Belton'!$B$9:$B$64,Jun.26!F24) -> 0 | H24: =SUMIFS('Daily Belton'!$AK$9:$AK$64,'Daily Belton'!$A$9:$A$64,Jun.26!E24,'Daily Belton'!$B$9:$B$64,Jun.26!F24) -> 0 | I24: =SUMIFS('Daily Belton'!$AL$9:$AL$64,'Daily Belton'!$A$9:$A$64,Jun.26!E24,'Daily Belton'!$B$9:$B$64,Jun.26!F24) -> 0 | J24: =SUMIFS('Daily Belton'!$AM$9:$AM$64,'Daily Belton'!$A$9:$A$64,Jun.26!E24,'Daily Belton'!$B$9:$B$64,Jun.26!F24) -> 0 | K24: =H24/G24 -> #DIV/0! | L24: =IF(K24>1,"Achieved","Unachieved") -> #DIV/0!
A25: 2026 | B25: JUN | C25: BIT / FECL | D25: HDD | E25: =_xlfn.XLOOKUP(F25,'Daily Belton'!B:B,'Daily Belton'!C:C) -> A1(75ton) | F25: Tail Receiver Paris-C M3 | G25: =SUMIFS('Daily Belton'!$AJ$9:$AJ$64,'Daily Belton'!$A$9:$A$64,Jun.26!E25,'Daily Belton'!$B$9:$B$64,Jun.26!F25) -> 0 | H25: =SUMIFS('Daily Belton'!$AK$9:$AK$64,'Daily Belton'!$A$9:$A$64,Jun.26!E25,'Daily Belton'!$B$9:$B$64,Jun.26!F25) -> 0 | I25: =SUMIFS('Daily Belton'!$AL$9:$AL$64,'Daily Belton'!$A$9:$A$64,Jun.26!E25,'Daily Belton'!$B$9:$B$64,Jun.26!F25) -> 0 | J25: =SUMIFS('Daily Belton'!$AM$9:$AM$64,'Daily Belton'!$A$9:$A$64,Jun.26!E25,'Daily Belton'!$B$9:$B$64,Jun.26!F25) -> 0 | K25: =H25/G25 -> #DIV/0! | L25: =IF(K25>1,"Achieved","Unachieved") -> #DIV/0!
A26: 2026 | B26: JUN | C26: BIT / FECL | D26: HDD | E26: =_xlfn.XLOOKUP(F26,'Daily Belton'!B:B,'Daily Belton'!C:C) -> A1(75ton) | F26: Tail Receiver LDS M2 | G26: =SUMIFS('Daily Belton'!$AJ$9:$AJ$64,'Daily Belton'!$A$9:$A$64,Jun.26!E26,'Daily Belton'!$B$9:$B$64,Jun.26!F26) -> 300000 | H26: =SUMIFS('Daily Belton'!$AK$9:$AK$64,'Daily Belton'!$A$9:$A$64,Jun.26!E26,'Daily Belton'!$B$9:$B$64,Jun.26!F26) -> 301800 | I26: =SUMIFS('Daily Belton'!$AL$9:$AL$64,'Daily Belton'!$A$9:$A$64,Jun.26!E26,'Daily Belton'!$B$9:$B$64,Jun.26!F26) -> 493026 | J26: =SUMIFS('Daily Belton'!$AM$9:$AM$64,'Daily Belton'!$A$9:$A$64,Jun.26!E26,'Daily Belton'!$B$9:$B$64,Jun.26!F26) -> 495984.16 | K26: =H26/G26 -> 1.006 | L26: =IF(K26>1,"Achieved","Unachieved") -> Achieved
A27: 2026 | B27: JUN | C27: FECL | D27: HDD | E27: =_xlfn.XLOOKUP(F27,'Daily Fujikura'!B:B,'Daily Fujikura'!C:C) -> A3(50Ton) | F27: TYJ BOBBIN M1 | G27: =SUMIFS('Daily Fujikura'!$AJ$9:$AJ$50,'Daily Fujikura'!$A$9:$A$50,Jun.26!E27,'Daily Fujikura'!$B$9:$B$50,Jun.26!F27) -> 0 | H27: =SUMIFS('Daily Fujikura'!$AK$9:$AK$50,'Daily Fujikura'!$A$9:$A$50,Jun.26!E27,'Daily Fujikura'!$B$9:$B$50,Jun.26!F27) -> 0 | I27: =SUMIFS('Daily Fujikura'!$AL$9:$AL$50,'Daily Fujikura'!$A$9:$A$50,Jun.26!E27,'Daily Fujikura'!$B$9:$B$50,Jun.26!F27) -> 0 | J27: =SUMIFS('Daily Fujikura'!$AM$9:$AM$50,'Daily Fujikura'!$A$9:$A$50,Jun.26!E27,'Daily Fujikura'!$B$9:$B$50,Jun.26!F27) -> 0 | K27: =H27/G27 -> #DIV/0! | L27: =IF(K27>1,"Achieved","Unachieved") -> #DIV/0!
A28: 2026 | B28: JUN | C28: FECL | D28: HDD | E28: =_xlfn.XLOOKUP(F28,'Daily Fujikura'!B:B,'Daily Fujikura'!C:C) -> A4(40ton) | F28: TYU Bobbin (New material) M1 | G28: =SUMIFS('Daily Fujikura'!$AJ$9:$AJ$50,'Daily Fujikura'!$A$9:$A$50,Jun.26!E28,'Daily Fujikura'!$B$9:$B$50,Jun.26!F28) -> 250000 | H28: =SUMIFS('Daily Fujikura'!$AK$9:$AK$50,'Daily Fujikura'!$A$9:$A$50,Jun.26!E28,'Daily Fujikura'!$B$9:$B$50,Jun.26!F28) -> 228000 | I28: =SUMIFS('Daily Fujikura'!$AL$9:$AL$50,'Daily Fujikura'!$A$9:$A$50,Jun.26!E28,'Daily Fujikura'!$B$9:$B$50,Jun.26!F28) -> 699107.5 | J28: =SUMIFS('Daily Fujikura'!$AM$9:$AM$50,'Daily Fujikura'!$A$9:$A$50,Jun.26!E28,'Daily Fujikura'!$B$9:$B$50,Jun.26!F28) -> 637586.04 | K28: =H28/G28 -> 0.912 | L28: =IF(K28>1,"Achieved","Unachieved") -> Unachieved
A29: 2026 | B29: JUN | C29: FECL | D29: HDD | E29: =_xlfn.XLOOKUP(F29,'Daily Fujikura'!B:B,'Daily Fujikura'!C:C) -> A4(40ton) | F29: TYX BOBBIN(B) M1 | G29: =SUMIFS('Daily Fujikura'!$AJ$9:$AJ$50,'Daily Fujikura'!$A$9:$A$50,Jun.26!E29,'Daily Fujikura'!$B$9:$B$50,Jun.26!F29) -> 0 | H29: =SUMIFS('Daily Fujikura'!$AK$9:$AK$50,'Daily Fujikura'!$A$9:$A$50,Jun.26!E29,'Daily Fujikura'!$B$9:$B$50,Jun.26!F29) -> 24000 | I29: =SUMIFS('Daily Fujikura'!$AL$9:$AL$50,'Daily Fujikura'!$A$9:$A$50,Jun.26!E29,'Daily Fujikura'!$B$9:$B$50,Jun.26!F29) -> 0 | J29: =SUMIFS('Daily Fujikura'!$AM$9:$AM$50,'Daily Fujikura'!$A$9:$A$50,Jun.26!E29,'Daily Fujikura'!$B$9:$B$50,Jun.26!F29) -> 73741.44 | K29: =H29/G29 -> #DIV/0! | L29: =IF(K29>1,"Achieved","Unachieved") -> #DIV/0!
A30: 2026 | B30: JUN | C30: WDC | D30: RAMP | E30: =_xlfn.XLOOKUP(F30,'Daily Ramp'!B:B,'Daily Ramp'!C:C) -> R1(75*75ton) | F30: Ramp VL6, 4D (Vela-A) M1 | G30: =SUMIFS('Daily Ramp'!$AJ$8:$AJ$519,'Daily Ramp'!$A$8:$A$519,Jun.26!E30,'Daily Ramp'!$B$8:$B$519,Jun.26!F30) -> 0 | H30: =SUMIFS('Daily Ramp'!$AK$8:$AK$519,'Daily Ramp'!$A$8:$A$519,Jun.26!E30,'Daily Ramp'!$B$8:$B$519,Jun.26!F30) -> 0 | I30: =SUMIFS('Daily Ramp'!$AL$8:$AL$519,'Daily Ramp'!$A$8:$A$519,Jun.26!E30,'Daily Ramp'!$B$8:$B$519,Jun.26!F30) -> 0 | J30: =SUMIFS('Daily Ramp'!$AM$8:$AM$519,'Daily Ramp'!$A$8:$A$519,Jun.26!E30,'Daily Ramp'!$B$8:$B$519,Jun.26!F30) -> 0 | K30: =H30/G30 -> #DIV/0! | L30: =IF(K30>1,"Achieved","Unachieved") -> #DIV/0!
A31: 2026 | B31: JUN | C31: WDC | D31: RAMP | E31: =_xlfn.XLOOKUP(F31,'Daily Ramp'!B:B,'Daily Ramp'!C:C) -> R2(18ton) | F31: Ramp Paris-D M2 | G31: =SUMIFS('Daily Ramp'!$AJ$8:$AJ$519,'Daily Ramp'!$A$8:$A$519,Jun.26!E31,'Daily Ramp'!$B$8:$B$519,Jun.26!F31) -> 300000 | H31: =SUMIFS('Daily Ramp'!$AK$8:$AK$519,'Daily Ramp'!$A$8:$A$519,Jun.26!E31,'Daily Ramp'!$B$8:$B$519,Jun.26!F31) -> 98280 | I31: =SUMIFS('Daily Ramp'!$AL$8:$AL$519,'Daily Ramp'!$A$8:$A$519,Jun.26!E31,'Daily Ramp'!$B$8:$B$519,Jun.26!F31) -> 1614579 | J31: =SUMIFS('Daily Ramp'!$AM$8:$AM$519,'Daily Ramp'!$A$8:$A$519,Jun.26!E31,'Daily Ramp'!$B$8:$B$519,Jun.26!F31) -> 528936.08 | K31: =H31/G31 -> 0.3276 | L31: =IF(K31>1,"Achieved","Unachieved") -> Unachieved
A32: 2026 | B32: JUN | C32: WDC | D32: RAMP | E32: =_xlfn.XLOOKUP(F32,'Daily Ramp'!B:B,'Daily Ramp'!C:C) -> R3(18ton) | F32: Ramp Tressels M3 (RD450) | G32: =SUMIFS('Daily Ramp'!$AJ$8:$AJ$519,'Daily Ramp'!$A$8:$A$519,Jun.26!E32,'Daily Ramp'!$B$8:$B$519,Jun.26!F32) -> 0 | H32: =SUMIFS('Daily Ramp'!$AK$8:$AK$519,'Daily Ramp'!$A$8:$A$519,Jun.26!E32,'Daily Ramp'!$B$8:$B$519,Jun.26!F32) -> 0 | I32: =SUMIFS('Daily Ramp'!$AL$8:$AL$519,'Daily Ramp'!$A$8:$A$519,Jun.26!E32,'Daily Ramp'!$B$8:$B$519,Jun.26!F32) -> 0 | J32: =SUMIFS('Daily Ramp'!$AM$8:$AM$519,'Daily Ramp'!$A$8:$A$519,Jun.26!E32,'Daily Ramp'!$B$8:$B$519,Jun.26!F32) -> 0 | K32: =H32/G32 -> #DIV/0! | L32: =IF(K32>1,"Achieved","Unachieved") -> #DIV/0!
A33: 2026 | B33: JUN | C33: WDC | D33: RAMP | E33: =_xlfn.XLOOKUP(F33,'Daily Ramp'!B:B,'Daily Ramp'!C:C) -> R4(18ton) | F33: Ramp Tressels M4 (RD450) | G33: =SUMIFS('Daily Ramp'!$AJ$8:$AJ$519,'Daily Ramp'!$A$8:$A$519,Jun.26!E33,'Daily Ramp'!$B$8:$B$519,Jun.26!F33) -> 0 | H33: =SUMIFS('Daily Ramp'!$AK$8:$AK$519,'Daily Ramp'!$A$8:$A$519,Jun.26!E33,'Daily Ramp'!$B$8:$B$519,Jun.26!F33) -> 0 | I33: =SUMIFS('Daily Ramp'!$AL$8:$AL$519,'Daily Ramp'!$A$8:$A$519,Jun.26!E33,'Daily Ramp'!$B$8:$B$519,Jun.26!F33) -> 0 | J33: =SUMIFS('Daily Ramp'!$AM$8:$AM$519,'Daily Ramp'!$A$8:$A$519,Jun.26!E33,'Daily Ramp'!$B$8:$B$519,Jun.26!F33) -> 0 | K33: =H33/G33 -> #DIV/0! | L33: =IF(K33>1,"Achieved","Unachieved") -> #DIV/0!
A34: 2026 | B34: JUN | C34: WDC | D34: RAMP | E34: =_xlfn.XLOOKUP(F34,'Daily Ramp'!B:B,'Daily Ramp'!C:C) -> R5(18ton) | F34: Ramp Laguna97/Carmel M1 | G34: =SUMIFS('Daily Ramp'!$AJ$8:$AJ$519,'Daily Ramp'!$A$8:$A$519,Jun.26!E34,'Daily Ramp'!$B$8:$B$519,Jun.26!F34) -> 0 | H34: =SUMIFS('Daily Ramp'!$AK$8:$AK$519,'Daily Ramp'!$A$8:$A$519,Jun.26!E34,'Daily Ramp'!$B$8:$B$519,Jun.26!F34) -> 0 | I34: =SUMIFS('Daily Ramp'!$AL$8:$AL$519,'Daily Ramp'!$A$8:$A$519,Jun.26!E34,'Daily Ramp'!$B$8:$B$519,Jun.26!F34) -> 0 | J34: =SUMIFS('Daily Ramp'!$AM$8:$AM$519,'Daily Ramp'!$A$8:$A$519,Jun.26!E34,'Daily Ramp'!$B$8:$B$519,Jun.26!F34) -> 0 | K34: =H34/G34 -> #DIV/0! | L34: =IF(K34>1,"Achieved","Unachieved") -> #DIV/0!
A35: 2026 | B35: JUN | C35: WDC | D35: RAMP | E35: =_xlfn.XLOOKUP(F35,'Daily Ramp'!B:B,'Daily Ramp'!C:C) -> R5(18ton) | F35: Ramp Carmel RP M1 | G35: =SUMIFS('Daily Ramp'!$AJ$8:$AJ$519,'Daily Ramp'!$A$8:$A$519,Jun.26!E35,'Daily Ramp'!$B$8:$B$519,Jun.26!F35) -> 456000 | H35: =SUMIFS('Daily Ramp'!$AK$8:$AK$519,'Daily Ramp'!$A$8:$A$519,Jun.26!E35,'Daily Ramp'!$B$8:$B$519,Jun.26!F35) -> 553600 | I35: =SUMIFS('Daily Ramp'!$AL$8:$AL$519,'Daily Ramp'!$A$8:$A$519,Jun.26!E35,'Daily Ramp'!$B$8:$B$519,Jun.26!F35) -> 1683907.7 | J35: =SUMIFS('Daily Ramp'!$AM$8:$AM$519,'Daily Ramp'!$A$8:$A$519,Jun.26!E35,'Daily Ramp'!$B$8:$B$519,Jun.26!F35) -> 2044323 | K35: =H35/G35 -> 1.2140351 | L35: =IF(K35>1,"Achieved","Unachieved") -> Achieved
A36: 2026 | B36: JUN | C36: WDC | D36: RAMP | E36: =_xlfn.XLOOKUP(F36,'Daily Ramp'!B:B,'Daily Ramp'!C:C) -> R16(18 ton) | F36: Ramp Carmel RP M2 | G36: =SUMIFS('Daily Ramp'!$AJ$8:$AJ$519,'Daily Ramp'!$A$8:$A$519,Jun.26!E36,'Daily Ramp'!$B$8:$B$519,Jun.26!F36) -> 344000 | H36: =SUMIFS('Daily Ramp'!$AK$8:$AK$519,'Daily Ramp'!$A$8:$A$519,Jun.26!E36,'Daily Ramp'!$B$8:$B$519,Jun.26!F36) -> 465600 | I36: =SUMIFS('Daily Ramp'!$AL$8:$AL$519,'Daily Ramp'!$A$8:$A$519,Jun.26!E36,'Daily Ramp'!$B$8:$B$519,Jun.26!F36) -> 1270316.3 | J36: =SUMIFS('Daily Ramp'!$AM$8:$AM$519,'Daily Ramp'!$A$8:$A$519,Jun.26!E36,'Daily Ramp'!$B$8:$B$519,Jun.26!F36) -> 1719358.4 | K36: =H36/G36 -> 1.3534884 | L36: =IF(K36>1,"Achieved","Unachieved") -> Achieved
A37: 2026 | B37: JUN | C37: WDC | D37: RAMP | E37: =_xlfn.XLOOKUP(F37,'Daily Ramp'!B:B,'Daily Ramp'!C:C) -> R6(18ton) | F37: Ramp Fblite M2 | G37: =SUMIFS('Daily Ramp'!$AJ$8:$AJ$519,'Daily Ramp'!$A$8:$A$519,Jun.26!E37,'Daily Ramp'!$B$8:$B$519,Jun.26!F37) -> 0 | H37: =SUMIFS('Daily Ramp'!$AK$8:$AK$519,'Daily Ramp'!$A$8:$A$519,Jun.26!E37,'Daily Ramp'!$B$8:$B$519,Jun.26!F37) -> 0 | I37: =SUMIFS('Daily Ramp'!$AL$8:$AL$519,'Daily Ramp'!$A$8:$A$519,Jun.26!E37,'Daily Ramp'!$B$8:$B$519,Jun.26!F37) -> 0 | J37: =SUMIFS('Daily Ramp'!$AM$8:$AM$519,'Daily Ramp'!$A$8:$A$519,Jun.26!E37,'Daily Ramp'!$B$8:$B$519,Jun.26!F37) -> 0 | K37: =H37/G37 -> #DIV/0! | L37: =IF(K37>1,"Achieved","Unachieved") -> #DIV/0!
A38: 2026 | B38: JUN | C38: WDC | D38: RAMP | E38: =_xlfn.XLOOKUP(F38,'Daily Ramp'!B:B,'Daily Ramp'!C:C) -> R7(75*75ton) | F38: Ramp, Spoiler - Dual shot Carmel 2D M1 | G38: =SUMIFS('Daily Ramp'!$AJ$8:$AJ$519,'Daily Ramp'!$A$8:$A$519,Jun.26!E38,'Daily Ramp'!$B$8:$B$519,Jun.26!F38) -> 150000 | H38: =SUMIFS('Daily Ramp'!$AK$8:$AK$519,'Daily Ramp'!$A$8:$A$519,Jun.26!E38,'Daily Ramp'!$B$8:$B$519,Jun.26!F38) -> 158720 | I38: =SUMIFS('Daily Ramp'!$AL$8:$AL$519,'Daily Ramp'!$A$8:$A$519,Jun.26!E38,'Daily Ramp'!$B$8:$B$519,Jun.26!F38) -> 556983 | J38: =SUMIFS('Daily Ramp'!$AM$8:$AM$519,'Daily Ramp'!$A$8:$A$519,Jun.26!E38,'Daily Ramp'!$B$8:$B$519,Jun.26!F38) -> 589362.28 | K38: =H38/G38 -> 1.0581333 | L38: =IF(K38>1,"Achieved","Unachieved") -> Achieved
A39: 2026 | B39: JUN | C39: WDC | D39: RAMP | E39: =_xlfn.XLOOKUP(F39,'Daily Ramp'!B:B,'Daily Ramp'!C:C) -> R8(18ton) | F39: Ramp Spyglass M2 | G39: =SUMIFS('Daily Ramp'!$AJ$8:$AJ$519,'Daily Ramp'!$A$8:$A$519,Jun.26!E39,'Daily Ramp'!$B$8:$B$519,Jun.26!F39) -> 150000 | H39: =SUMIFS('Daily Ramp'!$AK$8:$AK$519,'Daily Ramp'!$A$8:$A$519,Jun.26!E39,'Daily Ramp'!$B$8:$B$519,Jun.26!F39) -> 439200 | I39: =SUMIFS('Daily Ramp'!$AL$8:$AL$519,'Daily Ramp'!$A$8:$A$519,Jun.26!E39,'Daily Ramp'!$B$8:$B$519,Jun.26!F39) -> 658773 | J39: =SUMIFS('Daily Ramp'!$AM$8:$AM$519,'Daily Ramp'!$A$8:$A$519,Jun.26!E39,'Daily Ramp'!$B$8:$B$519,Jun.26!F39) -> 1928887.3 | K39: =H39/G39 -> 2.928 | L39: =IF(K39>1,"Achieved","Unachieved") -> Achieved
A40: 2026 | B40: JUN | C40: WDC | D40: RAMP | E40: =_xlfn.XLOOKUP(F40,'Daily Ramp'!B:B,'Daily Ramp'!C:C) -> R9(18ton) | F40: Ramp London-D M4 (Nominal) | G40: =SUMIFS('Daily Ramp'!$AJ$8:$AJ$519,'Daily Ramp'!$A$8:$A$519,Jun.26!E40,'Daily Ramp'!$B$8:$B$519,Jun.26!F40) -> 100000 | H40: =SUMIFS('Daily Ramp'!$AK$8:$AK$519,'Daily Ramp'!$A$8:$A$519,Jun.26!E40,'Daily Ramp'!$B$8:$B$519,Jun.26!F40) -> 0 | I40: =SUMIFS('Daily Ramp'!$AL$8:$AL$519,'Daily Ramp'!$A$8:$A$519,Jun.26!E40,'Daily Ramp'!$B$8:$B$519,Jun.26!F40) -> 586918 | J40: =SUMIFS('Daily Ramp'!$AM$8:$AM$519,'Daily Ramp'!$A$8:$A$519,Jun.26!E40,'Daily Ramp'!$B$8:$B$519,Jun.26!F40) -> 0 | K40: =H40/G40 -> 0 | L40: =IF(K40>1,"Achieved","Unachieved") -> Unachieved
A41: 2026 | B41: JUN | C41: WDC | D41: RAMP | E41: =_xlfn.XLOOKUP(F41,'Daily Ramp'!B:B,'Daily Ramp'!C:C) -> R9(18ton) | F41: Ramp London-D M4 (High) | G41: =SUMIFS('Daily Ramp'!$AJ$8:$AJ$519,'Daily Ramp'!$A$8:$A$519,Jun.26!E41,'Daily Ramp'!$B$8:$B$519,Jun.26!F41) -> 0 | H41: =SUMIFS('Daily Ramp'!$AK$8:$AK$519,'Daily Ramp'!$A$8:$A$519,Jun.26!E41,'Daily Ramp'!$B$8:$B$519,Jun.26!F41) -> 0 | I41: =SUMIFS('Daily Ramp'!$AL$8:$AL$519,'Daily Ramp'!$A$8:$A$519,Jun.26!E41,'Daily Ramp'!$B$8:$B$519,Jun.26!F41) -> 0 | J41: =SUMIFS('Daily Ramp'!$AM$8:$AM$519,'Daily Ramp'!$A$8:$A$519,Jun.26!E41,'Daily Ramp'!$B$8:$B$519,Jun.26!F41) -> 0 | K41: =H41/G41 -> #DIV/0! | L41: =IF(K41>1,"Achieved","Unachieved") -> #DIV/0!
... A60: 2026 | B60: JUN | C60: WDC | D60: RAMP | E60: =_xlfn.XLOOKUP(F60,'Daily Ramp'!B:B,'Daily Ramp'!C:C) -> R24(50ton) | F60: Ramp Sydney-E M4 (Nominal) | G60: =SUMIFS('Daily Ramp'!$AJ$8:$AJ$519,'Daily Ramp'!$A$8:$A$519,Jun.26!E60,'Daily Ramp'!$B$8:$B$519,Jun.26!F60) -> 100000 | H60: =SUMIFS('Daily Ramp'!$AK$8:$AK$519,'Daily Ramp'!$A$8:$A$519,Jun.26!E60,'Daily Ramp'!$B$8:$B$519,Jun.26!F60) -> 15300 | I60: =SUMIFS('Daily Ramp'!$AL$8:$AL$519,'Daily Ramp'!$A$8:$A$519,Jun.26!E60,'Daily Ramp'!$B$8:$B$519,Jun.26!F60) -> 686772 | J60: =SUMIFS('Daily Ramp'!$AM$8:$AM$519,'Daily Ramp'!$A$8:$A$519,Jun.26!E60,'Daily Ramp'!$B$8:$B$519,Jun.26!F60) -> 105076.12 | K60: =H60/G60 -> 0.153 | L60: =IF(K60>1,"Achieved","Unachieved") -> Unachieved
A61: 2026 | B61: JUN | C61: ADVICS | D61: AUTO | E61: =_xlfn.XLOOKUP(F61,'Daily Advics'!B:B,'Daily Advics'!C:C) -> A3(50Ton) | F61: RING , FEED M1 | G61: =SUMIFS('Daily Advics'!$AJ$9:$AJ$78,'Daily Advics'!$A$9:$A$78,Jun.26!E61,'Daily Advics'!$B$9:$B$78,Jun.26!F61) -> 0 | H61: =SUMIFS('Daily Advics'!$AK$9:$AK$78,'Daily Advics'!$A$9:$A$78,Jun.26!E61,'Daily Advics'!$B$9:$B$78,Jun.26!F61) -> 0 | I61: =SUMIFS('Daily Advics'!$AL$9:$AL$78,'Daily Advics'!$A$9:$A$78,Jun.26!E61,'Daily Advics'!$B$9:$B$78,Jun.26!F61) -> 0 | J61: =SUMIFS('Daily Advics'!$AM$9:$AM$78,'Daily Advics'!$A$9:$A$78,Jun.26!E61,'Daily Advics'!$B$9:$B$78,Jun.26!F61) -> 0 | K61: =H61/G61 -> #DIV/0! | L61: =IF(K61>1,"Achieved","Unachieved") -> #DIV/0!
A62: 2026 | B62: JUN | C62: ADVICS | D62: AUTO | E62: =_xlfn.XLOOKUP(F62,'Daily Advics'!B:B,'Daily Advics'!C:C) -> A15(50Ton) | F62: CYLINDER , PUMP M1 | G62: =SUMIFS('Daily Advics'!$AJ$9:$AJ$78,'Daily Advics'!$A$9:$A$78,Jun.26!E62,'Daily Advics'!$B$9:$B$78,Jun.26!F62) -> 0 | H62: =SUMIFS('Daily Advics'!$AK$9:$AK$78,'Daily Advics'!$A$9:$A$78,Jun.26!E62,'Daily Advics'!$B$9:$B$78,Jun.26!F62) -> 0 | I62: =SUMIFS('Daily Advics'!$AL$9:$AL$78,'Daily Advics'!$A$9:$A$78,Jun.26!E62,'Daily Advics'!$B$9:$B$78,Jun.26!F62) -> 0 | J62: =SUMIFS('Daily Advics'!$AM$9:$AM$78,'Daily Advics'!$A$9:$A$78,Jun.26!E62,'Daily Advics'!$B$9:$B$78,Jun.26!F62) -> 0 | K62: =H62/G62 -> #DIV/0! | L62: =IF(K62>1,"Achieved","Unachieved") -> #DIV/0!
...

Sheet Daily Tray 
AB2: 151431
D3: Rev.1
A4: Production Daily Output for Tray Air Spoiler and Ramp in June 2026
A5: INJ sent to TL and related section before noon.
A6: M/C No. | B6: Part Name | C6: Std. O/H (Shot) | D6: Date | E6: June'2026 | F6: Column1 | G6: Column2 | H6: Column3 | I6: Column4 | J6: Column5 | K6: Column6 | L6: Column7 | M6: Column8 | N6: Column9 | O6: Column10 | P6: Column11 | Q6: Column12 | R6: Column13 | S6: Column14 | T6: Column15 | U6: Column16 | V6: Column17 | W6: Column18 | X6: Column19 | Y6: Column20 | Z6: Column21 | AA6: Column22 | AB6: Column23 | AC6: Column24 | AD6: Column242 | AE6: Column243 | AF6: Column244 | AG6: Column25 | AH6: Column26 | AI6: Column27 | AJ6: Total | AK6: Total Act. (pcs.) | AL6: Sale/Bahts. | AM6: Total Amount (THB) | AN6: Price/Pcs. | AO6: Material usage (Kg) | AP6: Column28 | AQ6: Column29 | AR6: Column30 | AS6: Column31 | AT6: Column32 | AU6: Column33 | AV6: Column35
E7: 46174 | F7: =Table75[[#This Row],[June''2026]]+1 -> 46175 | G7: =Table75[[#This Row],[Column1]]+1 -> 46176 | H7: =Table75[[#This Row],[Column2]]+1 -> 46177 | I7: =Table75[[#This Row],[Column3]]+1 -> 46178 | J7: =Table75[[#This Row],[Column4]]+1 -> 46179 | K7: =Table75[[#This Row],[Column5]]+1 -> 46180 | L7: =Table75[[#This Row],[Column6]]+1 -> 46181 | M7: =Table75[[#This Row],[Column7]]+1 -> 46182 | N7: =Table75[[#This Row],[Column8]]+1 -> 46183 | O7: =Table75[[#This Row],[Column9]]+1 -> 46184 | P7: =Table75[[#This Row],[Column10]]+1 -> 46185 | Q7: =Table75[[#This Row],[Column11]]+1 -> 46186 | R7: =Table75[[#This Row],[Column12]]+1 -> 46187 | S7: =Table75[[#This Row],[Column13]]+1 -> 46188 | T7: =Table75[[#This Row],[Column14]]+1 -> 46189 | U7: =Table75[[#This Row],[Column15]]+1 -> 46190 | V7: =Table75[[#This Row],[Column16]]+1 -> 46191 | W7: =Table75[[#This Row],[Column17]]+1 -> 46192 | X7: =Table75[[#This Row],[Column18]]+1 -> 46193 | Y7: =Table75[[#This Row],[Column19]]+1 -> 46194 | Z7: =Table75[[#This Row],[Column20]]+1 -> 46195 | AA7: =Table75[[#This Row],[Column21]]+1 -> 46196 | AB7: =Table75[[#This Row],[Column22]]+1 -> 46197 | AC7: =Table75[[#This Row],[Column23]]+1 -> 46198 | AD7: =Table75[[#This Row],[Column24]]+1 -> 46199 | AE7: =Table75[[#This Row],[Column242]]+1 -> 46200 | AF7: =Table75[[#This Row],[Column243]]+1 -> 46201 | AG7: =Table75[[#This Row],[Column244]]+1 -> 46202 | AH7: =Table75[[#This Row],[Column25]]+1 -> 46203 | AI7: =Table75[[#This Row],[Column26]]+1 -> 46204 | AK7: =AJ9 -> 0 | AM7: =AL9 -> 0
B8: Tray for Ramp Vela-A (Color Green) | D8: Plan (pcs.) | AJ8: =SUM(E8:AI8) -> 0 | AK8: =AJ10 -> 0 | AL8: =+AJ8*AN8 -> 0 | AM8: =AL10 -> 0 | AO8: =Table5[[#This Row],[Total]]*B12/1000 -> 0 | AP8: M/C A7 | AQ8: WK1 | AR8: WK2 | AS8: WK3 | AT8: WK4 | AU8: WK5 | AV8: Total
B9: AME3962-00 | D9: Accumulated shot count | E9: =IF(E8="",0,+ E8/E15) -> 0 | F9: =IF(F8="",0, E9+F8/F15) -> 0 | G9: =IF(G8="",0, F9+G8/G15) -> 0 | H9: =IF(H8="",0, G9+H8/H15) -> 0 | I9: =IF(I8="",0, H9+I8/I15) -> 0 | J9: =IF(J8="",0, I9+J8/J15) -> 0 | K9: =IF(K8="",0, J9+K8/K15) -> 0 | L9: =IF(L8="",0, K9+L8/L15) -> 0 | M9: =IF(M8="",0, L9+M8/M15) -> 0 | ... AI9: =IF(AI8="",0, AH9+AI8/AI15) -> 0 | AM9: =AL11 -> 0 | AP9: Plan (pcs) | AQ9: =SUM(E8:I8) -> 0 | AR9: =SUM(J8:P8) -> 0 | AS9: =SUM(Q8:W8) -> 0 | AT9: =SUM(X8:AD8) -> 0 | AU9: =SUM(AE8:AI8) -> 0 | AV9: =SUM(AQ9:AU9) -> 0
B10: 1/1 cav. | D10: Actual (pcs.) | AJ10: =SUM(E10:AI10) -> 0 | AL10: =+AJ10*AN8 -> 0 | AM10: =AL12 -> 0 | AO10: =(AJ10+AJ12+AJ13+AJ14)*B12/1000 -> 0 | AP10: Actual (pcs) | AQ10: =SUM(E10:I10) -> 0 | AR10: =SUM(J10:P10) -> 0 | AS10: =SUM(Q10:W10) -> 0 | AT10: =SUM(X10:AD10) -> 0 | AU10: =SUM(AE10:AI10) -> 0 | AV10: =SUM(AQ10:AU10) -> 0
C11: STD. shot mold O/H | D11: Diff.from plan (pcs.) | E11: =+E10-E8 -> 0 | F11: =+F10-F8 -> 0 | G11: =+G10-G8 -> 0 | H11: =+H10-H8 -> 0 | I11: =+I10-I8 -> 0 | J11: =+J10-J8 -> 0 | K11: =+K10-K8 -> 0 | L11: =+L10-L8 -> 0 | ... AJ11: =+AJ10-AJ8 -> 0 | AL11: =+AJ11*AN8 -> 0 | AM11: =AL13 -> 0 | AN11: % Defect | AP11: Deff.(pcs.) | AQ11: =AQ10-AQ9 -> 0 | AR11: =AR10-AR9 -> 0 | AS11: =AS10-AS9 -> 0 | AT11: =AT10-AT9 -> 0 | AU11: =AU10-AU9 -> 0 | AV11: =SUM(AQ11:AU11) -> 0
A12: A7 (75tons) | C12: 1time/month | D12: Throw away (pcs.) | AJ12: =SUM(E12:AI12) -> 0 | AL12: =+AJ12*AN8 -> 0 | AM12: =AL14 -> 0 | AN12: =+AJ12/AJ10*100 -> #DIV/0! | AO12: =AO10/AO8 -> #DIV/0! | AP12: Throwaway(pcs) | AQ12: =SUM(E12:I12) -> 0 | AR12: =SUM(J12:P12) -> 0 | AS12: =SUM(Q12:W12) -> 0 | AT12: =SUM(X12:AD12) -> 0 | AU12: =SUM(AE12:AI12) -> 0 | AV12: =SUM(AQ12:AU12) -> 0
D13: QC Sample partrol (pcs.) | AJ13: =SUM(E13:AI13) -> 0 | AL13: =+AJ13*AN8 -> 0 | AM13: =AL15 -> 0 | AP13: Throwaway cost (THB) | AQ13: =AQ12*AN8 -> 0 | AR13: =AR12*AN8 -> 0 | AS13: =AS12*AN8 -> 0 | AT13: =AT12*AN8 -> 0 | AU13: =AU12*AN8 -> 0 | AV13: =SUM(AQ13:AU13) -> 0
C14: Screw O/H | D14: INJ. Sample partrol (pcs.) | AJ14: =SUM(E14:AI14) -> 0 | AL14: =+AJ14*AN9 -> 0 | AM14: =AL16 -> 0 | AP14: Production amount(THB) | AQ14: =AQ10*AN8 -> 0 | AR14: =AR10*AN8 -> 0 | AS14: =AS10*AN8 -> 0 | AT14: =AT10*AN8 -> 0 | AU14: =AU10*AN8 -> 0 | AV14: =SUM(AQ14:AU14) -> 0
C15: 300000 | D15: Actual cav. | E15: 1 | F15: 1 | G15: 1 | H15: 1 | I15: 1 | J15: 1 | K15: 1 | L15: 1 | M15: 1 | N15: 1 | O15: 1 | P15: 1 | Q15: 1 | R15: 1 | S15: 1 | T15: 1 | U15: 1 | V15: 1 | W15: 1 | X15: 1 | Y15: 1 | Z15: 1 | AA15: 1 | AB15: 1 | AC15: 1 | AD15: 1 | AE15: 1 | AF15: 1 | AG15: 1 | AH15: 1 | AI15: 1 | AM15: =AL17 -> 0
C16: Trigger line | D16: Shot cont | E16: =SUM(E10+E12+E13+E14)/E15 -> 0 | F16: =SUM(F10+F12+F13+F14)/F15 -> 0 | G16: =SUM(G10+G12+G13+G14)/G15 -> 0 | H16: =SUM(H10+H12+H13+H14)/H15 -> 0 | I16: =SUM(I10+I12+I13+I14)/I15 -> 0 | J16: =SUM(J10+J12+J13+J14)/J15 -> 0 | K16: =SUM(K10+K12+K13+K14)/K15 -> 0 | L16: =SUM(L10+L12+L13+L14)/L15 -> 0 | ... AI16: =SUM(AI10+AI12+AI13+AI14)/AI15 -> 0 | AJ16: =SUM(E16:AI16) -> 0 | AM16: =AL18 -> 0
C17: =+C15*0.8 -> 240000 | D17: Mold O/H | AM17: =AL19 -> 0
D18: Actual accumulated shot count | E18: =IF(E17="O/H",E16,0+E16) -> 0 | F18: =IF(F17="O/H",F16,+E18+F16) -> 0 | G18: =IF(G17="O/H",G16,+F18+G16) -> 0 | H18: =IF(H17="O/H",H16,+G18+H16) -> 0 | I18: =IF(I17="O/H",I16,+H18+I16) -> 0 | J18: =IF(J17="O/H",J16,+I18+J16) -> 0 | K18: =IF(K17="O/H",K16,+J18+K16) -> 0 | L18: =IF(L17="O/H",L16,+K18+L16) -> 0 | M18: =IF(M17="O/H",M16,+L18+M16) -> 0 | ... AI18: =IF(AI17="O/H",AI16,+AH18+AI16) -> 0 | AM18: =AL20 -> 0
D19: Total Mold Shot counter Actual | E19: =IF(AND(ISNUMBER(E10)),151896+E16) -> FALSE | F19: =IF(AND(ISNUMBER(F10)),E19+F16,"") | G19: =IF(AND(ISNUMBER(G10)),F19+G16,"") | H19: =IF(AND(ISNUMBER(H10)),G19+H16,"") | I19: =IF(AND(ISNUMBER(I10)),H19+I16,"") | J19: =IF(AND(ISNUMBER(J10)),I19+J16,"") | K19: =IF(AND(ISNUMBER(K10)),J19+K16,"") | L19: =IF(AND(ISNUMBER(L10)),K19+L16,"") | M19: =IF(AND(ISNUMBER(M10)),L19+M16,"") | ... AI19: =IF(AND(ISNUMBER(AI10)),AH19+AI16,"") | AM19: =AL21 -> 0
D20: Screw O/H | AM20: =AL22 -> 0
D21: Actual accumulated shot count | E21: =IF(E20="O/H",E16,0+E16) -> 0 | F21: =IF(F20="O/H",F16,+E21+F16) -> 0 | G21: =IF(G20="O/H",G16,+F21+G16) -> 0 | H21: =IF(H20="O/H",H16,+G21+H16) -> 0 | I21: =IF(I20="O/H",I16,+H21+I16) -> 0 | J21: =IF(J20="O/H",J16,+I21+J16) -> 0 | K21: =IF(K20="O/H",K16,+J21+K16) -> 0 | L21: =IF(L20="O/H",L16,+K21+L16) -> 0 | M21: =IF(M20="O/H",M16,+L21+M16) -> 0 | ... AI21: =IF(AI20="O/H",AI16,+AH21+AI16) -> 0 | AM21: =AL23 -> 0
B22: Bar for Ramp Vela-A (Color Green) | D22: Plan (pcs.) | AJ22: =SUM(Table75[[#This Row],[June''2026]:[Column27]]) -> 0 | AK22: =AJ24 -> 0 | AL22: =+AJ22*AN22 -> 0 | AM22: =AL24 -> 0 | AO22: =Table5[[#This Row],[Total]]*B26/1000 -> 0 | AP22: M/C A7 | AQ22: WK1 | AR22: WK2 | AS22: WK3 | AT22: WK4 | AU22: WK5 | AV22: Total
B23: - | D23: Accumulated shot count | E23: =IF(E22="",0,+ E22/E29) -> 0 | F23: =IF(F22="",0, E23+F22/F29) -> 0 | G23: =IF(G22="",0, F23+G22/G29) -> 0 | H23: =IF(H22="",0, G23+H22/H29) -> 0 | I23: =IF(I22="",0, H23+I22/I29) -> 0 | J23: =IF(J22="",0, I23+J22/J29) -> 0 | K23: =IF(K22="",0, J23+K22/K29) -> 0 | L23: =IF(L22="",0, K23+L22/L29) -> 0 | M23: =IF(M22="",0, L23+M22/M29) -> 0 | ... AI23: =IF(AI22="",0, AH23+AI22/AI29) -> 0 | AM23: =AL25 -> 0 | AP23: Plan (pcs) | AQ23: =SUM(E22:I22) -> 0 | AR23: =SUM(J22:P22) -> 0 | AS23: =SUM(Q22:W22) -> 0 | AT23: =SUM(X22:AD22) -> 0 | AU23: =SUM(AE22:AI22) -> 0 | AV23: =SUM(AQ23:AU23) -> 0
B24: 1/1 cav. | D24: Actual (pcs.) | AJ24: =SUM(E24:AI24) -> 0 | AL24: =+AJ24*AN22 -> 0 | AM24: =AL26 -> 0 | AO24: =(AJ24+AJ26+AJ27+AJ28)*B26/1000 -> 0 | AP24: Actual (pcs) | AQ24: =SUM(E24:I24) -> 0 | AR24: =SUM(J24:P24) -> 0 | AS24: =SUM(Q24:W24) -> 0 | AT24: =SUM(X24:AD24) -> 0 | AU24: =SUM(AE24:AI24) -> 0 | AV24: =SUM(AQ24:AU24) -> 0
C25: STD. shot mold O/H | D25: Diff.from plan (pcs.) | E25: =+E24-E22 -> 0 | F25: =+F24-F22 -> 0 | G25: =+G24-G22 -> 0 | H25: =+H24-H22 -> 0 | I25: =+I24-I22 -> 0 | J25: =+J24-J22 -> 0 | K25: =+K24-K22 -> 0 | L25: =+L24-L22 -> 0 | ... AJ25: =+AJ24-AJ22 -> 0 | AL25: =+AJ25*AN22 -> 0 | AM25: =AL27 -> 0 | AN25: % Defect | AP25: Deff.(pcs.) | AQ25: =AQ24-AQ23 -> 0 | AR25: =AR24-AR23 -> 0 | AS25: =AS24-AS23 -> 0 | AT25: =AT24-AT23 -> 0 | AU25: =AU24-AU23 -> 0 | AV25: =SUM(AQ25:AU25) -> 0
C26: 1time/month | D26: Throw away (pcs.) | AJ26: =SUM(E26:AI26) -> 0 | AL26: =+AJ26*AN22 -> 0 | AM26: =AL28 -> 0 | AN26: =+AJ26/AJ24*100 -> #DIV/0! | AO26: =AO24/AO22 -> #DIV/0! | AP26: Throwaway(pcs) | AQ26: =SUM(E26:I26) -> 0 | AR26: =SUM(J26:P26) -> 0 | AS26: =SUM(Q26:W26) -> 0 | AT26: =SUM(X26:AD26) -> 0 | AU26: =SUM(AE26:AI26) -> 0 | AV26: =SUM(AQ26:AU26) -> 0
A27: A7 (75tons) | D27: QC Sample partrol (pcs.) | AJ27: =SUM(E27:AI27) -> 0 | AL27: =+AJ27*AN22 -> 0 | AM27: =AL29 -> 0 | AP27: Throwaway cost (THB) | AQ27: =AQ26*AN22 -> 0 | AR27: =AR26*AN22 -> 0 | AS27: =AS26*AN22 -> 0 | AT27: =AT26*AN22 -> 0 | AU27: =AU26*AN22 -> 0 | AV27: =SUM(AQ27:AU27) -> 0
C28: Screw O/H | D28: INJ. Sample partrol (pcs.) | AJ28: =SUM(E28:AI28) -> 0 | AL28: =+AJ28*AN22 -> 0 | AM28: =AL30 -> 0 | AP28: Production amount(THB) | AQ28: =AQ24*AN22 -> 0 | AR28: =AR24*AN22 -> 0 | AS28: =AS24*AN22 -> 0 | AT28: =AT24*AN22 -> 0 | AU28: =AU24*AN22 -> 0 | AV28: =SUM(AQ28:AU28) -> 0
C29: 300000 | D29: Actual cav. | E29: 1 | F29: 1 | G29: 1 | H29: 1 | I29: 1 | J29: 1 | K29: 1 | L29: 1 | M29: 1 | N29: 1 | O29: 1 | P29: 1 | Q29: 1 | R29: 1 | S29: 1 | T29: 1 | U29: 1 | V29: 1 | W29: 1 | X29: 1 | Y29: 1 | Z29: 1 | AA29: 1 | AB29: 1 | AC29: 1 | AD29: 1 | AE29: 1 | AF29: 1 | AG29: 1 | AH29: 1 | AI29: 1 | AM29: =AL31 -> 0
C30: Trigger line | D30: Shot cont | E30: =SUM(E24+E26+E27+E28)/E29 -> 0 | F30: =SUM(F24+F26+F27+F28)/F29 -> 0 | G30: =SUM(G24+G26+G27+G28)/G29 -> 0 | H30: =SUM(H24+H26+H27+H28)/H29 -> 0 | I30: =SUM(I24+I26+I27+I28)/I29 -> 0 | J30: =SUM(J24+J26+J27+J28)/J29 -> 0 | K30: =SUM(K24+K26+K27+K28)/K29 -> 0 | L30: =SUM(L24+L26+L27+L28)/L29 -> 0 | ... AH30: =SUM(AH24+AH26+AH27+AH28)/AH29 -> 0 | AI30: =SUM(AI24+AI26+AI27)/AI29 -> 0 | AJ30: =SUM(E30:AI30) -> 0 | AM30: =AL32 -> 0
C31: =+C29*0.8 -> 240000 | D31: Mold O/H | AM31: =AL33 -> 0
D32: Actual accumulated shot count | E32: =IF(E31="O/H",E30,0+E30) -> 0 | F32: =IF(F31="O/H",F30,+E32+F30) -> 0 | G32: =IF(G31="O/H",G30,+F32+G30) -> 0 | H32: =IF(H31="O/H",H30,+G32+H30) -> 0 | I32: =IF(I31="O/H",I30,+H32+I30) -> 0 | J32: =IF(J31="O/H",J30,+I32+J30) -> 0 | K32: =IF(K31="O/H",K30,+J32+K30) -> 0 | L32: =IF(L31="O/H",L30,+K32+L30) -> 0 | M32: =IF(M31="O/H",M30,+L32+M30) -> 0 | ... AI32: =IF(AI31="O/H",AI30,+AH32+AI30) -> 0 | AM32: =AL34 -> 0
D33: Total Mold Shot counter Actual | E33: =IF(AND(ISNUMBER(E24)),1361139+E30) -> FALSE | F33: =IF(AND(ISNUMBER(F24)),E33+F30,"") | G33: =IF(AND(ISNUMBER(G24)),F33+G30,"") | H33: =IF(AND(ISNUMBER(H24)),G33+H30,"") | I33: =IF(AND(ISNUMBER(I24)),H33+I30,"") | J33: =IF(AND(ISNUMBER(J24)),I33+J30,"") | K33: =IF(AND(ISNUMBER(K24)),J33+K30,"") | L33: =IF(AND(ISNUMBER(L24)),K33+L30,"") | M33: =IF(AND(ISNUMBER(M24)),L33+M30,"") | ... AI33: =IF(AND(ISNUMBER(AI24)),AH33+AI30,"") | AM33: =AL35 -> 0
D34: Screw O/H | AM34: =AL36 -> 0
D35: Actual accumulated shot count | E35: =IF(E34="O/H",E30,0+E30) -> 0 | F35: =IF(F34="O/H",F30,+E35+F30) -> 0 | G35: =IF(G34="O/H",G30,+F35+G30) -> 0 | H35: =IF(H34="O/H",H30,+G35+H30) -> 0 | I35: =IF(I34="O/H",I30,+H35+I30) -> 0 | J35: =IF(J34="O/H",J30,+I35+J30) -> 0 | K35: =IF(K34="O/H",K30,+J35+K30) -> 0 | L35: =IF(L34="O/H",L30,+K35+L30) -> 0 | M35: =IF(M34="O/H",M30,+L35+M30) -> 0 | ... AI35: =IF(AI34="O/H",AI30,+AH35+AI30) -> 0 | AM35: =AL37 -> 0
B36: Tray for Ramp Vela-A1 (Carina2) Color Blue | D36: Plan (pcs.) | AJ36: =SUM(Table75[[#This Row],[June''2026]:[Column27]]) -> 0 | AK36: =AJ38 -> 0 | AL36: =+AJ36*AN36 -> 0 | AM36: =AL38 -> 0 | AO36: =Table5[[#This Row],[Total]]*B40/1000 -> 0 | AP36: M/C A7 | AQ36: WK1 | AR36: WK2 | AS36: WK3 | AT36: WK4 | AU36: WK5 | AV36: Total
B37: C53610 | D37: Accumulated shot count | E37: =IF(E36="",0,+ E36/E43) -> 0 | F37: =IF(F36="",0, E37+F36/F43) -> 0 | G37: =IF(G36="",0, F37+G36/G43) -> 0 | H37: =IF(H36="",0, G37+H36/H43) -> 0 | I37: =IF(I36="",0, H37+I36/I43) -> 0 | J37: =IF(J36="",0, I37+J36/J43) -> 0 | K37: =IF(K36="",0, J37+K36/K43) -> 0 | L37: =IF(L36="",0, K37+L36/L43) -> 0 | M37: =IF(M36="",0, L37+M36/M43) -> 0 | ... AI37: =IF(AI36="",0, AH37+AI36/AI43) -> 0 | AM37: =AL39 -> 0 | AP37: Plan (pcs) | AQ37: =SUM(E36:I36) -> 0 | AR37: =SUM(J36:P36) -> 0 | AS37: =SUM(Q36:W36) -> 0 | AT37: =SUM(X36:AD36) -> 0 | AU37: =SUM(AE36:AI36) -> 0 | AV37: =SUM(AQ37:AU37) -> 0
B38: 1/1 cav. | D38: Actual (pcs.) | AJ38: =SUM(E38:AI38) -> 0 | AL38: =+AJ38*AN36 -> 0 | AM38: =AL40 -> 0 | AO38: =(AJ38+AJ40+AJ41+AJ42)*B40/1000 -> 0 | AP38: Actual (pcs) | AQ38: =SUM(E38:I38) -> 0 | AR38: =SUM(J38:P38) -> 0 | AS38: =SUM(Q38:W38) -> 0 | AT38: =SUM(X38:AD38) -> 0 | AU38: =SUM(AE38:AI38) -> 0 | AV38: =SUM(AQ38:AU38) -> 0
C39: STD. shot mold O/H | D39: Diff.from plan (pcs.) | E39: =+E38-E36 -> 0 | F39: =+F38-F36 -> 0 | G39: =+G38-G36 -> 0 | H39: =+H38-H36 -> 0 | I39: =+I38-I36 -> 0 | J39: =+J38-J36 -> 0 | K39: =+K38-K36 -> 0 | L39: =+L38-L36 -> 0 | ... AJ39: =+AJ38-AJ36 -> 0 | AL39: =+AJ39*AN36 -> 0 | AM39: =AL41 -> 0 | AN39: % Defect | AP39: Deff.(pcs.) | AQ39: =AQ38-AQ37 -> 0 | AR39: =AR38-AR37 -> 0 | AS39: =AS38-AS37 -> 0 | AT39: =AT38-AT37 -> 0 | AU39: =AU38-AU37 -> 0 | AV39: =SUM(AQ39:AU39) -> 0
C40: 1time/month | D40: Throw away (pcs.) | AJ40: =SUM(E40:AI40) -> 0 | AL40: =+AJ40*AN36 -> 0 | AM40: =AL42 -> 0 | AN40: =+AJ40/AJ38*100 -> #DIV/0! | AO40: =AO38/AO36 -> #DIV/0! | AP40: Throwaway(pcs) | AQ40: =SUM(E40:I40) -> 0 | AR40: =SUM(J40:P40) -> 0 | AS40: =SUM(Q40:W40) -> 0 | AT40: =SUM(X40:AD40) -> 0 | AU40: =SUM(AE40:AI40) -> 0 | AV40: =SUM(AQ40:AU40) -> 0
A41: A7 (75tons) | D41: QC Sample partrol (pcs.) | AJ41: =SUM(E41:AI41) -> 0 | AL41: =+AJ41*AN36 -> 0 | AM41: =AL43 -> 0 | AP41: Throwaway cost (THB) | AQ41: =AQ40*AN36 -> 0 | AR41: =AR40*AN36 -> 0 | AS41: =AS40*AN36 -> 0 | AT41: =AT40*AN36 -> 0 | AU41: =AU40*AN36 -> 0 | AV41: =SUM(AQ41:AU41) -> 0
...

Sheet SUMMARY
B1: 1. Monitoring PD Output accumulated (each Product group)
B3: PD Output | C3: Ramp | D3: HDD (Air/Bobbin/Latch/ Filter case/TC/BR) | E3: AUTO | F3: SEAGATE | G3: Belton | I3: TTL Product | J3: Tray | K3: TTL w/ Tray
A4: Quantity | B4: Plan | C4: ='Daily Ramp'!AJ520 -> 3120000 | D4: ='Daily WDC'!AJ583+'Daily Nidec'!AJ50+'Daily Fujikura'!AJ51+'Daily Belton'!AJ65 -> 4039000 | E4: ='Daily Advics'!AJ79+'Daily TRT '!AJ237+'Daily Yazaki'!AJ177 -> 850000 | F4: ='Daily Seagate'!AJ23 -> 0 | I4: =SUM(C4:F4) -> 8009000 | K4: =I4+J4 -> 8009000 | L4: Pcs.
B5: Actual | C5: ='Daily Ramp'!AJ521 -> 2793222 | D5: ='Daily WDC'!AJ584+'Daily Nidec'!AJ51+'Daily Fujikura'!AJ52+'Daily Belton'!AJ66 -> 3423884 | E5: ='Daily Advics'!AJ80+'Daily TRT '!AJ238+'Daily Yazaki'!AJ178 -> 719124 | F5: ='Daily Seagate'!AJ24 -> 0 | I5: =SUM(C5:F5) -> 6936230 | K5: =I5+J5 -> 6936230 | L5: Pcs.
B6: Diff. (pcs.) | C6: =C5-C4 -> -326778 | D6: =D5-D4 -> -615116 | E6: =E5-E4 -> -130876 | F6: =F5-F4 -> 0 | I6: =I5-I4 -> -1072770 | K6: =K5-K4 -> -1072770
B7: %Achievement | C7: =C5/C4 -> 0.89526346 | D7: =D5/D4 -> 0.84770587 | E7: =E5/E4 -> 0.84602824 | F7: =F5/F4 -> #DIV/0! | I7: =I5/I4 -> 0.86605444 | K7: =K5/K4 -> 0.86605444
A8: Amount | B8: Plan | C8: ='Daily Ramp'!AL520 -> 16104081 | D8: ='Daily WDC'!AL583+'Daily Nidec'!AL50+'Daily Fujikura'!AL51+'Daily Belton'!AL65 -> 16162855 | E8: ='Daily Advics'!AL79+'Daily TRT '!AL237+'Daily Yazaki'!AL177 -> 2773007 | F8: ='Daily Seagate'!AL23 -> 0 | I8: =SUM(C8:F8) -> 35039943 | L8: THB
B9: Actual | C9: ='Daily Ramp'!AL521 -> 13371259 | D9: ='Daily WDC'!AL584+'Daily Nidec'!AL51+'Daily Fujikura'!AL52+'Daily Belton'!AL66 -> 14120181 | E9: ='Daily Advics'!AL80+'Daily TRT '!AL238+'Daily Yazaki'!AL178 -> 2007694.8 | F9: ='Daily Seagate'!AV37 -> 0 | I9: =SUM(C9:F9) -> 29499135 | K9: =I9+J9 -> 29499135 | L9: THB
B10: Diff. (THB) | C10: =C9-C8 -> -2732822.4 | D10: =D9-D8 -> -2042674 | E10: =E9-E8 -> -765312.21 | F10: =F9-F8 -> 0 | G10: =G9-G8 -> 0 | H10: =H9-H8 -> 0 | I10: =I9-I8 -> -5540808.6
B11: % Achievement | C11: =C9/C8 -> 0.83030249 | D11: =D9/D8 -> 0.87361923 | E11: =E9/E8 -> 0.7240136 | F11: =F9/F8 -> #DIV/0! | G11: =G9/G8 -> #DIV/0! | H11: =H9/H8 -> #DIV/0! | I11: =I9/I8 -> 0.84187164
B12: Throwaway cost (THB) | C12: ='Daily Ramp'!AV532 -> 559415.35 | D12: ='Daily WDC'!AV596+'Daily Nidec'!AV63+'Daily Fujikura'!AV64+'Daily Belton'!AV78 -> 170940.24 | E12: ='Daily Advics'!AV91+'Daily TRT '!AV249+'Daily Yazaki'!AV190 -> 41092.455 | F12: ='Daily Seagate'!AV36 -> 0 | I12: =SUM(C12:F12) -> 771448.04
B13: % Throwaway | C13: =C12/C9 -> 0.04183715 | D13: =D12/D9 -> 0.012106094 | E13: =E12/E9 -> 0.020467481 | F13: =F12/F9 -> #DIV/0! | G13: =G12/G9 -> #DIV/0! | H13: =H12/H9 -> #DIV/0! | I13: =I12/I9 -> 0.026151548
A15: Q'ty | B15: Actual | C15: =ROUND(C5/1000000,1)&" Mpcs." -> 2.8 Mpcs. | D15: =ROUND(D5/1000000,1)&" Mpcs." -> 3.4 Mpcs. | E15: =ROUND(E5/1000000,1)&" Mpcs." -> 0.7 Mpcs. | F15: =ROUND(F5/1000,1)&" Kpcs." -> 0 Kpcs. | G15: =ROUND(G4/1000000,1)&" Mpcs." -> 0 Mpcs. | H15: =ROUND(H4/1000000,1)&" Mpcs." -> 0 Mpcs. | I15: =ROUND(I5/1000000,1)&" Mpcs." -> 6.9 Mpcs.
B16: Diff. | C16: =ROUND(C6/1000000,1)&" Mpcs." -> -0.3 Mpcs. | D16: =ROUND(D6/1000000,1)&" Mpcs." -> -0.6 Mpcs. | E16: =ROUND(E6/1000000,1)&" Mpcs." -> -0.1 Mpcs. | F16: =ROUND(F6/1000,1)&" Kpcs." -> 0 Kpcs. | G16: =ROUND(G6/1000000,1)&" Mpcs." -> 0 Mpcs. | H16: =ROUND(H6/1000000,1)&" Mpcs." -> 0 Mpcs. | I16: =ROUND(I6/1000000,1)&" Mpcs." -> -1.1 Mpcs.
B17: Plan | C17: =ROUND(C4/1000000,1)&" Mpcs." -> 3.1 Mpcs. | D17: =ROUND(D4/1000000,1)&" Mpcs." -> 4 Mpcs. | E17: =ROUND(E4/1000000,1)&" Mpcs." -> 0.9 Mpcs. | F17: =ROUND(F4/1000,1)&" Kpcs." -> 0 Kpcs. | G17: =ROUND(G4/1000000,1)&" Mpcs." -> 0 Mpcs. | H17: =ROUND(H4/1000000,1)&" Mpcs." -> 0 Mpcs. | I17: =ROUND(I4/1000000,1)&" Mpcs." -> 8 Mpcs.
B18: %Achievement | C18: =C7 -> 0.89526346 | D18: =D7 -> 0.84770587 | E18: =E7 -> 0.84602824 | F18: =F7 -> #DIV/0! | G18: =G7 -> 0 | H18: =H7 -> 0 | I18: =I7 -> 0.86605444
A19: Amount | B19: Actual | C19: =ROUND(C9/1000000,1)&" MB" -> 13.4 MB | D19: =ROUND(D9/1000000,1)&" MB" -> 14.1 MB | E19: =ROUND(E9/1000000,1)&" MB" -> 2 MB | F19: =ROUND(F9/1000000,1)&" MB" -> 0 MB | G19: =ROUND(G9/1000000,1)&" MB" -> 0 MB | H19: =ROUND(H9/1000000,1)&" MB" -> 0 MB | I19: =ROUND(I9/1000000,1)&" MB" -> 29.5 MB
B20: Diff. | C20: =ROUND(C10/1000000,1)&" MB" -> -2.7 MB | D20: =ROUND(D10/1000000,1)&" MB" -> -2 MB | E20: =ROUND(E10/1000000,1)&" MB" -> -0.8 MB | F20: =ROUND(F10/1000000,1)&" MB" -> 0 MB | G20: =ROUND(G10/1000000,1)&" MB" -> 0 MB | H20: =ROUND(H10/1000000,1)&" MB" -> 0 MB | I20: =ROUND(I10/1000000,1)&" MB" -> -5.5 MB
B21: Plan | C21: =ROUND(C8/1000000,1)&" MB" -> 16.1 MB | D21: =ROUND(D8/1000000,1)&" MB" -> 16.2 MB | E21: =ROUND(E8/1000000,1)&" MB" -> 2.8 MB | F21: =ROUND(F8/1000000,1)&" MB" -> 0 MB | G21: =ROUND(G8/1000000,1)&" MB" -> 0 MB | H21: =ROUND(H8/1000000,1)&" MB" -> 0 MB | I21: =ROUND(I8/1000000,1)&" MB" -> 35 MB
B22: %Achievement | C22: =C11 -> 0.83030249 | D22: =D11 -> 0.87361923 | E22: =E11 -> 0.7240136 | F22: =F11 -> #DIV/0! | G22: =G11 -> #DIV/0! | H22: =H11 -> #DIV/0! | I22: =I11 -> 0.84187164
B37: 2. Material Usage Monitoring
A38: No. | B38: Material name | C38: Ratio | D38: Plan Usage (kg.) | E38: Actual Usage (kg.) | F38: %Usage
A39: 1 | B39: Tenac-C_RD450 V66810R | C39: 1
A40: 2 | B40: Tenac-C_RD450 V66810R | C40: 50:50

Sheet Daily Advics
D4: Rev.1
A5: Production Daily Output for Automotive part in June 2026
A6: INJ sent to TL and related section before noon.
A7: M/C No. | B7: Part Name | C7: Std. O/H (Shot) | D7: Date | E7: June'2026 | F7: Column1 | G7: Column2 | H7: Column3 | I7: Column4 | J7: Column5 | K7: Column6 | L7: Column7 | M7: Column8 | N7: Column9 | O7: Column10 | P7: Column11 | Q7: Column12 | R7: Column13 | S7: Column14 | T7: Column15 | U7: Column16 | V7: Column17 | W7: Column18 | X7: Column19 | Y7: Column20 | Z7: Column21 | AA7: Column22 | AB7: Column23 | AC7: Column24 | AD7: Column25 | AE7: Column26 | AF7: Column262 | AG7: Column263 | AH7: Column264 | AI7: Column27 | AJ7: Total | AK7: Total Act. (pcs.) | AL7: Sale/Bahts. | AM7: Total Amount (THB) | AN7: Price/Pcs. | AO7: Material usage (Kg) | AP7: Column28 | AQ7: Column29 | AR7: Column30 | AS7: Column31 | AT7: Column32 | AU7: Column33 | AV7: Column35
E8: 46174 | F8: =Table5[[#This Row],[June''2026]]+1 -> 46175 | G8: =Table5[[#This Row],[Column1]]+1 -> 46176 | H8: =Table5[[#This Row],[Column2]]+1 -> 46177 | I8: =Table5[[#This Row],[Column3]]+1 -> 46178 | J8: =Table5[[#This Row],[Column4]]+1 -> 46179 | K8: =Table5[[#This Row],[Column5]]+1 -> 46180 | L8: =Table5[[#This Row],[Column6]]+1 -> 46181 | M8: =Table5[[#This Row],[Column7]]+1 -> 46182 | N8: =Table5[[#This Row],[Column8]]+1 -> 46183 | O8: =Table5[[#This Row],[Column9]]+1 -> 46184 | P8: =Table5[[#This Row],[Column10]]+1 -> 46185 | Q8: =Table5[[#This Row],[Column11]]+1 -> 46186 | R8: =Table5[[#This Row],[Column12]]+1 -> 46187 | S8: =Table5[[#This Row],[Column13]]+1 -> 46188 | T8: =Table5[[#This Row],[Column14]]+1 -> 46189 | U8: =Table5[[#This Row],[Column15]]+1 -> 46190 | V8: =Table5[[#This Row],[Column16]]+1 -> 46191 | W8: =Table5[[#This Row],[Column17]]+1 -> 46192 | X8: =Table5[[#This Row],[Column18]]+1 -> 46193 | Y8: =Table5[[#This Row],[Column19]]+1 -> 46194 | Z8: =Table5[[#This Row],[Column20]]+1 -> 46195 | AA8: =Table5[[#This Row],[Column21]]+1 -> 46196 | AB8: =Table5[[#This Row],[Column22]]+1 -> 46197 | AC8: =Table5[[#This Row],[Column23]]+1 -> 46198 | AD8: =Table5[[#This Row],[Column24]]+1 -> 46199 | AE8: =Table5[[#This Row],[Column25]]+1 -> 46200 | AF8: =Table5[[#This Row],[Column26]]+1 -> 46201 | AG8: =Table5[[#This Row],[Column262]]+1 -> 46202 | AH8: =Table5[[#This Row],[Column263]]+1 -> 46203 | AI8: =Table5[[#This Row],[Column264]]+1 -> 46204
A9: A3(50Ton) | B9: RING , FEED M1 | C9: =Table5[[#This Row],[M/C No.]] -> A3(50Ton) | D9: Plan (pcs.) | AJ9: =SUM(E9:AI9) -> 0 | AK9: =AJ11 -> 0 | AL9: =+AJ9*AN9 -> 0 | AM9: =AL11 -> 0 | AN9: 1.88977 | AO9: =Table5[[#This Row],[Total]]*B13/1000 -> 0 | AP9: M/C A3 | AQ9: WK1 | AR9: WK2 | AS9: WK3 | AT9: WK4 | AU9: WK5 | AV9: Total
B10: 113233-40010-C | D10: Accumulated shot count | E10: =IF(E9="",0,+ E9/E16) -> 0 | F10: =IF(F9="",0, E10+F9/F16) -> 0 | G10: =IF(G9="",0, F10+G9/G16) -> 0 | H10: =IF(H9="",0, G10+H9/H16) -> 0 | I10: =IF(I9="",0, H10+I9/I16) -> 0 | J10: =IF(J9="",0, I10+J9/J16) -> 0 | K10: =IF(K9="",0, J10+K9/K16) -> 0 | L10: =IF(L9="",0, K10+L9/L16) -> 0 | M10: =IF(M9="",0, L10+M9/M16) -> 0 | ... AC10: =IF(AC9="",0, AB10+AC9/AC16) -> 0 | AD10: =IF(AD9="",0, Z10+AD9/AD16) -> 0 | AE10: =IF(AE9="",0, AA10+AE9/AE16) -> 0 | AF10: =IF(AF9="",0, AB10+AF9/AF16) -> 0 | AG10: =IF(AG9="",0, AC10+AG9/AG16) -> 0 | AH10: =IF(AH9="",0, AD10+AH9/AH16) -> 0 | AI10: =IF(AI9="",0, AH10+AI9/AI16) -> 0 | AK10: =AJ12 -> 0 | AM10: =AL12 -> 0 | AP10: Plan (pcs) | AQ10: =SUM(E9:I9) -> 0 | AR10: =SUM(J9:P9) -> 0 | AS10: =SUM(Q9:W9) -> 0 | AT10: =SUM(X9:AD9) -> 0 | AU10: =SUM(AE9:AI9) -> 0 | AV10: =SUM(AQ10:AU10) -> 0
A11: A15 | B11: 4/4 Cav. | D11: Actual (pcs.) | AJ11: =SUM(E11:AI11) -> 0 | AK11: =AJ13 -> 0 | AL11: =+AJ11*AN9 -> 0 | AM11: =AL13 -> 0 | AO11: =(AJ11+AJ13+AJ14+AJ15)*B13/1000 -> 0 | AP11: Actual (pcs) | AQ11: =SUM(E11:I11) -> 0 | AR11: =SUM(J11:P11) -> 0 | AS11: =SUM(Q11:W11) -> 0 | AT11: =SUM(X11:AD11) -> 0 | AU11: =SUM(AE11:AI11) -> 0 | AV11: =SUM(AQ11:AU11) -> 0
A12: A15 | B12: Part weight (g) | C12: STD. shot mold O/H | D12: Diff.from plan (pcs.) | E12: =+E11-E9 -> 0 | F12: =+F11-F9 -> 0 | G12: =+G11-G9 -> 0 | H12: =+H11-H9 -> 0 | I12: =+I11-I9 -> 0 | J12: =+J11-J9 -> 0 | K12: =+K11-K9 -> 0 | L12: =+L11-L9 -> 0 | ... AJ12: =+AJ11-AJ9 -> 0 | AK12: =AJ14 -> 0 | AL12: =+AJ12*AN9 -> 0 | AM12: =AL14 -> 0 | AN12: % Defect | AP12: Deff.(pcs.) | AQ12: =AQ11-AQ10 -> 0 | AR12: =AR11-AR10 -> 0 | AS12: =AS11-AS10 -> 0 | AT12: =AT11-AT10 -> 0 | AU12: =AU11-AU10 -> 0 | AV12: =SUM(AQ12:AU12) -> 0
B13: 0.339 | C13: 1time/month | D13: Throw away (pcs.) | AJ13: =SUM(E13:AI13) -> 0 | AK13: =AJ15 -> 0 | AL13: =+AJ13*AN9 -> 0 | AM13: =AL15 -> 0 | AN13: =+AJ13/AJ11*100 -> #DIV/0! | AO13: =AO11/AO9 -> #DIV/0! | AP13: Throwaway(pcs) | AQ13: =SUM(E13:I13) -> 0 | AR13: =SUM(J13:P13) -> 0 | AS13: =SUM(Q13:W13) -> 0 | AT13: =SUM(X13:AD13) -> 0 | AU13: =SUM(AE13:AI13) -> 0 | AV13: =SUM(AQ13:AU13) -> 0
A14: A15 | B14: PA66 AMILAN CM3006 Z31 B2 BLACK | D14: QC Sample partrol (pcs.) | AJ14: =SUM(E14:AI14) -> 0 | AK14: =AJ16 -> 0 | AL14: =+AJ14*AN9 -> 0 | AM14: =AL16 -> 0 | AP14: Throwaway cost (THB) | AQ14: =AQ13*AN9 -> 0 | AR14: =AR13*AN9 -> 0 | AS14: =AS13*AN9 -> 0 | AT14: =AT13*AN9 -> 0 | AU14: =AU13*AN9 -> 0 | AV14: =SUM(AQ14:AU14) -> 0
A15: A15 | C15: Screw O/H | D15: INJ. Sample partrol (pcs.) | AJ15: =SUM(E15:AI15) -> 0 | AK15: =AJ17 -> 0 | AL15: =+AJ15*AN9 -> 0 | AM15: =AL17 -> 0 | AP15: Production amount(THB) | AQ15: =AQ11*AN9 -> 0 | AR15: =AR11*AN9 -> 0 | AS15: =AS11*AN9 -> 0 | AT15: =AT11*AN9 -> 0 | AU15: =AU11*AN9 -> 0 | AV15: =SUM(AQ15:AU15) -> 0
A16: A15 | C16: 300000 | D16: Actual cav. | E16: 4 | F16: 4 | G16: 4 | H16: 4 | I16: 4 | J16: 4 | K16: 4 | L16: 4 | M16: 4 | N16: 4 | O16: 4 | P16: 4 | Q16: 4 | R16: 4 | S16: 4 | T16: 4 | U16: 4 | V16: 4 | W16: 4 | X16: 4 | Y16: 4 | Z16: 4 | AA16: 4 | AB16: 4 | AC16: 4 | AD16: 4 | AE16: 4 | AF16: 4 | AG16: 4 | AH16: 4 | AI16: 4 | AK16: =AJ18 -> 0 | AM16: =AL18 -> 0
A17: A15 | C17: Trigger line | D17: Shot cont | E17: =SUM(E11+E13+E15+E14)/E16 -> 0 | F17: =SUM(F11+F13+F15+F14)/F16 -> 0 | G17: =SUM(G11+G13+G15+G14)/G16 -> 0 | H17: =SUM(H11+H13+H15+H14)/H16 -> 0 | I17: =SUM(I11+I13+I15+I14)/I16 -> 0 | J17: =SUM(J11+J13+J15+J14)/J16 -> 0 | K17: =SUM(K11+K13+K15+K14)/K16 -> 0 | L17: =SUM(L11+L13+L15+L14)/L16 -> 0 | ... AI17: =SUM(AI11+AI13+AI15+AI14)/AI16 -> 0 | AJ17: =SUM(E17:AI17) -> 0 | AK17: =AJ19 -> 0 | AM17: =AL19 -> 0
C18: =+C16*0.8 -> 240000 | D18: Mold O/H | AK18: =AJ20 -> 0 | AM18: =AL20 -> 0
D19: Actual accumulated shot count | E19: =IF(E18="O/H",E17,0+E17) -> 0 | F19: =IF(F18="O/H",F17,+E19+F17) -> 0 | G19: =IF(G18="O/H",G17,+F19+G17) -> 0 | H19: =IF(H18="O/H",H17,+G19+H17) -> 0 | I19: =IF(I18="O/H",I17,+H19+I17) -> 0 | J19: =IF(J18="O/H",J17,+I19+J17) -> 0 | K19: =IF(K18="O/H",K17,+J19+K17) -> 0 | L19: =IF(L18="O/H",L17,+K19+L17) -> 0 | M19: =IF(M18="O/H",M17,+L19+M17) -> 0 | ... AI19: =IF(AI18="O/H",AI17,+AH19+AI17) -> 0 | AK19: =AJ21 -> 0 | AM19: =AL21 -> 0
D20: Total Mold Shot counter Actual | E20: =IF(AND(ISNUMBER(E11)),1767483+E17) -> FALSE | F20: =IF(AND(ISNUMBER(F11)),E20+F17,"") | G20: =IF(AND(ISNUMBER(G11)),F20+G17,"") | H20: =IF(AND(ISNUMBER(H11)),G20+H17,"") | I20: =IF(AND(ISNUMBER(I11)),H20+I17,"") | J20: =IF(AND(ISNUMBER(J11)),I20+J17,"") | K20: =IF(AND(ISNUMBER(K11)),J20+K17,"") | L20: =IF(AND(ISNUMBER(L11)),K20+L17,"") | M20: =IF(AND(ISNUMBER(M11)),L20+M17,"") | ... AI20: =IF(AND(ISNUMBER(AI11)),AH20+AI17,"") | AK20: =AJ22 -> 0 | AM20: =AL22 -> 0
A21: A3 | B21: DV200-0000-90-0003 | D21: Screw O/H | AK21: =AJ23 -> 0 | AM21: =AL23 -> 0
A22: A3 | D22: Actual accumulated shot count | E22: =IF(E21="O/H",E17,295442+E17) -> 295442 | F22: =IF(F21="O/H",F17,+E22+F17) -> 295442 | G22: =IF(G21="O/H",G17,+F22+G17) -> 295442 | H22: =IF(H21="O/H",H17,+G22+H17) -> 295442 | I22: =IF(I21="O/H",I17,+H22+I17) -> 295442 | J22: =IF(J21="O/H",J17,+I22+J17) -> 295442 | K22: =IF(K21="O/H",K17,+J22+K17) -> 295442 | L22: =IF(L21="O/H",L17,+K22+L17) -> 295442 | M22: =IF(M21="O/H",M17,+L22+M17) -> 295442 | ... AI22: =IF(AI21="O/H",AI17,+AH22+AI17) -> 295442 | AK22: =AJ24 -> 0 | AM22: =AL24 -> 0
A23: A15(50Ton) | B23: CYLINDER , PUMP M1 | C23: =Table5[[#This Row],[M/C No.]] -> A15(50Ton) | D23: Plan (pcs.) | AJ23: =SUM(E23:AI23) -> 0 | AK23: =AJ25 -> 0 | AL23: =+AJ23*AN23 -> 0 | AM23: =AL25 -> 0 | AN23: 2.88999 | AO23: =Table5[[#This Row],[Total]]*B27/1000 -> 0 | AP23: M/C A15 | AQ23: WK1 | AR23: WK2 | AS23: WK3 | AT23: WK4 | AU23: WK5 | AV23: Total
B24: 113241-40010-A | D24: Accumulated shot count | E24: =IF(E23="",0,+ E23/E30) -> 0 | F24: =IF(F23="",0, E24+F23/F30) -> 0 | G24: =IF(G23="",0, F24+G23/G30) -> 0 | H24: =IF(H23="",0, G24+H23/H30) -> 0 | I24: =IF(I23="",0, H24+I23/I30) -> 0 | J24: =IF(J23="",0, I24+J23/J30) -> 0 | K24: =IF(K23="",0, J24+K23/K30) -> 0 | L24: =IF(L23="",0, K24+L23/L30) -> 0 | M24: =IF(M23="",0, L24+M23/M30) -> 0 | ... AC24: =IF(AC23="",0, AB24+AC23/AC30) -> 0 | AD24: =IF(AD23="",0, Z24+AD23/AD30) -> 0 | AE24: =IF(AE23="",0, AA24+AE23/AE30) -> 0 | AF24: =IF(AF23="",0, AB24+AF23/AF30) -> 0 | AG24: =IF(AG23="",0, AC24+AG23/AG30) -> 0 | AH24: =IF(AH23="",0, AD24+AH23/AH30) -> 0 | AI24: =IF(AI23="",0, AH24+AI23/AI30) -> 0 | AK24: =AJ26 -> 0 | AM24: =AL26 -> 0 | AP24: Plan (pcs) | AQ24: =SUM(E23:I23) -> 0 | AR24: =SUM(J23:P23) -> 0 | AS24: =SUM(Q23:W23) -> 0 | AT24: =SUM(X23:AD23) -> 0 | AU24: =SUM(AE23:AI23) -> 0 | AV24: =SUM(AQ24:AU24) -> 0
A25: A15 | B25: 4/4 Cav. | D25: Actual (pcs.) | E25: 0 | F25: 0 | G25: 0 | H25: 0 | I25: 0 | J25: 0 | K25: 0 | L25: 0 | M25: 0 | N25: 0 | O25: 0 | P25: 0 | Q25: 0 | R25: 0 | S25: 0 | T25: 0 | U25: 0 | V25: 0 | W25: 0 | X25: 0 | Y25: 0 | Z25: 0 | AA25: 0 | AJ25: =SUM(E25:AI25) -> 0 | AK25: =AJ27 -> 360 | AL25: =+AJ25*AN23 -> 0 | AM25: =AL27 -> 1040.3964 | AO25: =(AJ25+AJ27+AJ28+AJ29)*B27/1000 -> 0.47232 | AP25: Actual (pcs) | AQ25: =SUM(E25:I25) -> 0 | AR25: =SUM(J25:P25) -> 0 | AS25: =SUM(Q25:W25) -> 0 | AT25: =SUM(X25:AD25) -> 0 | AU25: =SUM(AE25:AI25) -> 0 | AV25: =SUM(AQ25:AU25) -> 0
A26: A15 | B26: Part weight (g) | C26: STD. shot mold O/H | D26: Diff.from plan (pcs.) | E26: =+E25-E23 -> 0 | F26: =+F25-F23 -> 0 | G26: =+G25-G23 -> 0 | H26: =+H25-H23 -> 0 | I26: =+I25-I23 -> 0 | J26: =+J25-J23 -> 0 | K26: =+K25-K23 -> 0 | L26: =+L25-L23 -> 0 | ... AJ26: =+AJ25-AJ23 -> 0 | AK26: =AJ28 -> 0 | AL26: =+AJ26*AN23 -> 0 | AM26: =AL28 -> 0 | AN26: % Defect | AP26: Deff.(pcs.) | AQ26: =AQ25-AQ24 -> 0 | AR26: =AR25-AR24 -> 0 | AS26: =AS25-AS24 -> 0 | AT26: =AT25-AT24 -> 0 | AU26: =AU25-AU24 -> 0 | AV26: =SUM(AQ26:AU26) -> 0
B27: 1.312 | C27: 1time/month | D27: Throw away (pcs.) | E27: 0 | F27: 0 | G27: 0 | H27: 0 | I27: 0 | J27: 0 | K27: 0 | L27: 0 | M27: 0 | N27: 0 | O27: 0 | P27: 0 | Q27: 0 | R27: 0 | S27: 0 | T27: 0 | U27: 0 | V27: 0 | W27: 0 | X27: 0 | Y27: 0 | Z27: 0 | AA27: 360 | AJ27: =SUM(E27:AI27) -> 360 | AK27: =AJ29 -> 0 | AL27: =+AJ27*AN23 -> 1040.3964 | AM27: =AL29 -> 0 | AN27: =+AJ27/AJ25*100 -> #DIV/0! | AO27: =AO25/AO23 -> #DIV/0! | AP27: Throwaway(pcs) | AQ27: =SUM(E27:I27) -> 0 | AR27: =SUM(J27:P27) -> 0 | AS27: =SUM(Q27:W27) -> 0 | AT27: =SUM(X27:AD27) -> 360 | AU27: =SUM(AE27:AI27) -> 0 | AV27: =SUM(AQ27:AU27) -> 360
