Workbook
Name \a: #REF!
Name \b: #REF!
Name \c: #REF!
Name __A1: [1]承認票!$J$2
Name __A815010: [2]参考!#REF!
Name __f05: #REF!
Name __MC300000: #REF!
Name __MC850001: #REF!
Name __MC860000: #REF!
Name __MC860001: #REF!
Name __MC860002: #REF!
Name __qqq10: #REF!
Name __qqq2: #REF!
Name __qqq3: #REF!
Name __qqq4: #REF!
Name __qqq5: #REF!
Name __qqq56: #REF!
Name __qqq8: #REF!
Name _1_0印: [3]社員リスト!#REF!
Name _A1: [1]承認票!$J$2
Name _A815010: [2]参考!#REF!
Name _f05: #REF!
Name _HK_TBL: #REF!
Name _MC300000: #REF!
Name _MC850001: #REF!
Name _MC860000: #REF!
Name _MC860001: #REF!
Name _MC860002: #REF!
Name _qqq10: #REF!
Name _qqq2: #REF!
Name _qqq3: #REF!
Name _qqq4: #REF!
Name _qqq5: #REF!
Name _qqq56: #REF!
Name _qqq7: #REF!
Name _qqq8: #REF!
Name _qqq9: #REF!
Name _RC29K_BMENG: [4]RCP作業!$O$1:$O$65536
Name _RC29N_MATNR: [4]RCP作業!$R$1:$R$65536
Name _RC29N_WERKS: [4]RCP作業!$S$1:$S$65536
Name _RC29P_IDNRK: [4]RCP作業!$AJ$1:$AJ$65536
Name _RC29P_MEINS: [4]RCP作業!$AM$1:$AM$65536
Name _RC29P_MENGE: [4]RCP作業!$AL$1:$AL$65536
Name _RC29P_POSNR: [4]RCP作業!$AI$1:$AI$65536
Name _RC29P_POSTP: [4]RCP作業!$AN$1
Name _RC29P_SORTF: [4]RCP作業!$AO$1:$AO$65536
Name _TK_TBL: #REF!
Name _価値低下区分: #REF!
Name _利用区分: #REF!
Name _地区区分: #REF!
Name _地目区分: #REF!
Name _奥行区分: #REF!
Name _評価区分: #REF!
Name A_1: #REF!
Name A_2: #REF!
Name A_3: #REF!
Name A_4: #REF!
Name A8150101: [2]参考!#REF!
Name A8150102: [2]参考!#REF!
Name A8150103: [2]参考!#REF!

Sheet Data
A1: 46082 | C1: 46082 | D1: =+C1+1 -> 46083 | E1: =+D1+1 -> 46084 | F1: =+E1+1 -> 46085 | G1: =+F1+1 -> 46086 | H1: =+G1+1 -> 46087 | I1: =+H1+1 -> 46088 | J1: =+I1+1 -> 46089 | K1: =+J1+1 -> 46090 | ... AG1: =+AF1+1 -> 46112
A3: =SUM(C3:AG3) -> 45361.273 | B3: PRB | C3: =C18+C22 -> 1169.4797 | D3: =D18+D22 -> 1229.0442 | E3: =E18+E22 -> 742.85025 | F3: =F18+F22 -> 1324.1315 | G3: =G18+G22 -> 2202.3747 | H3: =H18+H22 -> 1239.065 | I3: =I18+I22 -> 1386.9264 | J3: =J18+J22 -> 1212.6463 | ... AG3: =AG18+AG22 -> 1263.239 | AJ3: 31.2264
A4: =SUM(C4:AG4) -> 10009.148 | B4: BPI | C4: =C10+C14 -> 324.04275 | D4: =D10+D14 -> 370.16007 | E4: =E10+E14 -> 347.46712 | F4: =F10+F14 -> 341.77951 | G4: =G10+G14 -> 337.91108 | H4: =H10+H14 -> 310.54701 | I4: =I10+I14 -> 360.86409 | J4: =J10+J14 -> 339.83154 | ... AG4: =AG10+AG14 -> 213.1699
C5: =SUM(C3:C4) -> 1493.5225 | D5: =SUM(D3:D4) -> 1599.2043 | E5: =SUM(E3:E4) -> 1090.3174 | F5: =SUM(F3:F4) -> 1665.911 | G5: =SUM(G3:G4) -> 2540.2857 | H5: =SUM(H3:H4) -> 1549.612 | I5: =SUM(I3:I4) -> 1747.7905 | J5: =SUM(J3:J4) -> 1552.4779 | ... AG5: =SUM(AG3:AG4) -> 1476.4089
A7: Detail | C7: =A1 -> 46082 | D7: =+C7+1 -> 46083 | E7: =+D7+1 -> 46084 | F7: =+E7+1 -> 46085 | G7: =+F7+1 -> 46086 | H7: =+G7+1 -> 46087 | I7: =+H7+1 -> 46088 | J7: =+I7+1 -> 46089 | K7: =+J7+1 -> 46090 | ... AG7: =+AF7+1 -> 46112
B8: PLAN | C8: =$AK$84/31/1000 -> 94.8572 | D8: =$AK$84/31/1000 -> 94.8572 | E8: =$AK$84/31/1000 -> 94.8572 | F8: =$AK$84/31/1000 -> 94.8572 | G8: =$AK$84/31/1000 -> 94.8572 | H8: =$AK$84/31/1000 -> 94.8572 | I8: =$AK$84/31/1000 -> 94.8572 | J8: =$AK$84/31/1000 -> 94.8572 | ... AG8: =$AK$84/31/1000 -> 94.8572
A9: WD | B9: ACC PLAN | C9: =+C8 -> 94.8572 | D9: =C9+D8 -> 189.7144 | E9: =D9+E8 -> 284.5716 | F9: =E9+F8 -> 379.4288 | G9: =F9+G8 -> 474.286 | H9: =G9+H8 -> 569.1432 | I9: =H9+I8 -> 664.0004 | J9: =I9+J8 -> 758.8576 | K9: =J9+K8 -> 853.7148 | ... AG9: =AF9+AG8 -> 2940.5732
A10: INJ | B10: ACTUAL | C10: =+C93-C95 -> 111.84684 | D10: =+D93-D95 -> 104.83265 | E10: =+E93-E95 -> 111.84684 | F10: =+F93-F95 -> 104.83265 | G10: =+G93-G95 -> 130.65135 | H10: =+H93-H95 -> 111.84684 | I10: =+I93-I95 -> 104.83265 | J10: =+J93-J95 -> 121.58917 | ... AG10: =+AG93-AG95 -> 48.229072
B11: ACC ACTUAL | C11: =C10 -> 111.84684 | D11: =C11+D10 -> 216.67949 | E11: =D11+E10 -> 328.52633 | F11: =E11+F10 -> 433.35898 | G11: =F11+G10 -> 564.01033 | H11: =G11+H10 -> 675.85717 | I11: =H11+I10 -> 780.68982 | J11: =I11+J10 -> 902.27899 | K11: =J11+K10 -> 1023.8682 | ... AG11: =AF11+AG10 -> 3054.5704
B12: PLAN | C12: =$AK$85/31/1000 -> 189.57994 | D12: =$AK$85/31/1000 -> 189.57994 | E12: =$AK$85/31/1000 -> 189.57994 | F12: =$AK$85/31/1000 -> 189.57994 | G12: =$AK$85/31/1000 -> 189.57994 | H12: =$AK$85/31/1000 -> 189.57994 | I12: =$AK$85/31/1000 -> 189.57994 | J12: =$AK$85/31/1000 -> 189.57994 | ... AG12: =$AK$85/31/1000 -> 189.57994
A13: WD-BPI | B13: ACC PLAN | C13: =+C12 -> 189.57994 | D13: =C13+D12 -> 379.15988 | E13: =D13+E12 -> 568.73982 | F13: =E13+F12 -> 758.31976 | G13: =F13+G12 -> 947.89969 | H13: =G13+H12 -> 1137.4796 | I13: =H13+I12 -> 1327.0596 | J13: =I13+J12 -> 1516.6395 | K13: =J13+K12 -> 1706.2195 | ... AG13: =AF13+AG12 -> 5876.9781
A14: RAMP | B14: ACTUAL | C14: =+C95 -> 212.19591 | D14: =+D95 -> 265.32741 | E14: =+E95 -> 235.62029 | F14: =+F95 -> 236.94685 | G14: =+G95 -> 207.25973 | H14: =+H95 -> 198.70018 | I14: =+I95 -> 256.03143 | J14: =+J95 -> 218.24237 | ... AG14: =+AG95 -> 164.94083
B15: ACC ACTUAL | C15: =C14 -> 212.19591 | D15: =C15+D14 -> 477.52333 | E15: =D15+E14 -> 713.14361 | F15: =E15+F14 -> 950.09047 | G15: =F15+G14 -> 1157.3502 | H15: =G15+H14 -> 1356.0504 | I15: =H15+I14 -> 1612.0818 | J15: =I15+J14 -> 1830.3242 | K15: =J15+K14 -> 2111.3266 | ... AG15: =AF15+AG14 -> 6954.5774
B16: PLAN | C16: =$AK$86/31/1000 -> 373.04833 | D16: =$AK$86/31/1000 -> 373.04833 | E16: =$AK$86/31/1000 -> 373.04833 | F16: =$AK$86/31/1000 -> 373.04833 | G16: =$AK$86/31/1000 -> 373.04833 | H16: =$AK$86/31/1000 -> 373.04833 | I16: =$AK$86/31/1000 -> 373.04833 | J16: =$AK$86/31/1000 -> 373.04833 | ... AG16: =$AK$86/31/1000 -> 373.04833
A17: WD-PRB | B17: ACC PLAN | C17: =+C16 -> 373.04833 | D17: =C17+D16 -> 746.09665 | E17: =D17+E16 -> 1119.145 | F17: =E17+F16 -> 1492.1933 | G17: =F17+G16 -> 1865.2416 | H17: =G17+H16 -> 2238.29 | I17: =H17+I16 -> 2611.3383 | J17: =I17+J16 -> 2984.3866 | K17: =J17+K16 -> 3357.4349 | ... AG17: =AF17+AG16 -> 11564.498
A18: INJ | B18: ACTUAL | C18: =+C91-C22 -> 547.36013 | D18: =+D91-D22 -> 548.54842 | E18: =+E91-E22 -> 367.72743 | F18: =+F91-F22 -> 621.91242 | G18: =+G91-G22 -> 656.68597 | H18: =+H91-H22 -> 612.41334 | I18: =+I91-I22 -> 450.14761 | J18: =+J91-J22 -> 445.35846 | ... AG18: =+AG91-AG22 -> 480.97101
B19: ACC ACTUAL | C19: =C18 -> 547.36013 | D19: =C19+D18 -> 1095.9086 | E19: =D19+E18 -> 1463.636 | F19: =E19+F18 -> 2085.5484 | G19: =F19+G18 -> 2742.2344 | H19: =G19+H18 -> 3354.6477 | I19: =H19+I18 -> 3804.7953 | J19: =I19+J18 -> 4250.1538 | K19: =J19+K18 -> 4772.7328 | ... AG19: =AF19+AG18 -> 15125.622 | AH19: =AG19*1000 -> 15125622
B20: PLAN | C20: =$AK$87/31/1000 -> 811.14737 | D20: =$AK$87/31/1000 -> 811.14737 | E20: =$AK$87/31/1000 -> 811.14737 | F20: =$AK$87/31/1000 -> 811.14737 | G20: =$AK$87/31/1000 -> 811.14737 | H20: =$AK$87/31/1000 -> 811.14737 | I20: =$AK$87/31/1000 -> 811.14737 | J20: =$AK$87/31/1000 -> 811.14737 | ... AG20: =$AK$87/31/1000 -> 811.14737
A21: WD-PRB | B21: ACC PLAN | C21: =+C20 -> 811.14737 | D21: =C21+D20 -> 1622.2947 | E21: =D21+E20 -> 2433.4421 | F21: =E21+F20 -> 3244.5895 | G21: =F21+G20 -> 4055.7369 | H21: =G21+H20 -> 4866.8842 | I21: =H21+I20 -> 5678.0316 | J21: =I21+J20 -> 6489.179 | K21: =J21+K20 -> 7300.3263 | ... AG21: =AF21+AG20 -> 25145.569
A22: RAMP | B22: ACTUAL | C22: 622.11959 | D22: 680.49578 | E22: 375.12282 | F22: 702.21912 | G22: 1545.6887 | H22: 626.65161 | I22: 936.77884 | J22: 767.28785 | K22: 942.28891 | L22: 701.5102 | M22: 910.81042 | N22: 694.7839 | O22: 905.02309 | P22: 728.51668 | Q22: 895.99905 | R22: 600.00803 | S22: 887.02784 | T22: 1045.8091 | U22: 775.67674 | V22: 712.63349 | W22: 736.02785 | X22: 893.00302 | Y22: 958.41621 | Z22: 1028.8087 | AA22: 687.5259 | AB22: 744.15512 | AC22: 1119.723 | AD22: 886.74089 | AE22: 907.75531 | AF22: 5434.7756 | AG22: 782.26801
B23: ACC ACTUAL | C23: =C22 -> 622.11959 | D23: =C23+D22 -> 1302.6154 | E23: =D23+E22 -> 1677.7382 | F23: =E23+F22 -> 2379.9573 | G23: =F23+G22 -> 3925.646 | H23: =G23+H22 -> 4552.2976 | I23: =H23+I22 -> 5489.0764 | J23: =I23+J22 -> 6256.3643 | K23: =J23+K22 -> 7198.6532 | ... AG23: =AF23+AG22 -> 30235.651 | AH23: =+AG23*1000 -> 30235651
B24: PLAN | C24: =$AK$88/31/1000 -> 0 | D24: =$AK$88/31/1000 -> 0 | E24: =$AK$88/31/1000 -> 0 | F24: =$AK$88/31/1000 -> 0 | G24: =$AK$88/31/1000 -> 0 | H24: =$AK$88/31/1000 -> 0 | I24: =$AK$88/31/1000 -> 0 | J24: =$AK$88/31/1000 -> 0 | ... AG24: =$AK$88/31/1000 -> 0
A25: NETR | B25: ACC PLAN | C25: =+C24 -> 0 | D25: =C25+D24 -> 0 | E25: =D25+E24 -> 0 | F25: =E25+F24 -> 0 | G25: =F25+G24 -> 0 | H25: =G25+H24 -> 0 | I25: =H25+I24 -> 0 | J25: =I25+J24 -> 0 | K25: =J25+K24 -> 0 | ... AG25: =AF25+AG24 -> 0
B26: ACTUAL | C26: 0 | D26: 0 | E26: 0 | F26: 0 | G26: 0 | H26: 0 | I26: 0 | J26: 0 | K26: 0 | L26: 147.76868 | M26: 0 | N26: 0 | O26: 0 | P26: 0 | Q26: 0 | R26: 147.76868 | S26: 0 | T26: 0 | U26: 0 | V26: 147.76868 | W26: 0 | X26: 0 | Y26: 0 | Z26: 0 | AA26: 130.38413 | AB26: 0 | AC26: 0 | AD26: 0 | AE26: 0 | AF26: 0 | AG26: 0
B27: ACC ACTUAL | C27: =C26 -> 0 | D27: =C27+D26 -> 0 | E27: =D27+E26 -> 0 | F27: =E27+F26 -> 0 | G27: =F27+G26 -> 0 | H27: =G27+H26 -> 0 | I27: =H27+I26 -> 0 | J27: =I27+J26 -> 0 | K27: =J27+K26 -> 0 | ... AG27: =AF27+AG26 -> 573.69017 | AH27: =+AG27*1000 -> 573690.17
B28: PLAN | C28: =$AK$94/31/1000 -> 35.484242 | D28: =$AK$94/31/1000 -> 35.484242 | E28: =$AK$94/31/1000 -> 35.484242 | F28: =$AK$94/31/1000 -> 35.484242 | G28: =$AK$94/31/1000 -> 35.484242 | H28: =$AK$94/31/1000 -> 35.484242 | I28: =$AK$94/31/1000 -> 35.484242 | J28: =$AK$94/31/1000 -> 35.484242 | ... AG28: =$AK$94/31/1000 -> 35.484242
A29: Siam Aisin | B29: ACC PLAN | C29: =+C28 -> 35.484242 | D29: =C29+D28 -> 70.968484 | E29: =D29+E28 -> 106.45273 | F29: =E29+F28 -> 141.93697 | G29: =F29+G28 -> 177.42121 | H29: =G29+H28 -> 212.90545 | I29: =H29+I28 -> 248.38969 | J29: =I29+J28 -> 283.87394 | K29: =J29+K28 -> 319.35818 | ... AG29: =AF29+AG28 -> 1100.0115
B30: ACTUAL | C30: 0 | D30: 0 | E30: 0 | F30: =90.3105 -> 90.3105 | G30: =103.635 -> 103.635 | H30: =90.3105 -> 90.3105 | I30: 0 | J30: 0 | K30: =103.635 -> 103.635 | L30: =103.635 -> 103.635 | M30: =103.635 -> 103.635 | N30: =90.3105 -> 90.3105 | O30: 0 | P30: 0 | Q30: 0 | R30: =103.635 -> 103.635 | S30: =103.635 -> 103.635 | T30: =103.635 -> 103.635 | U30: =103.635 -> 103.635 | V30: 0 | W30: 0 | X30: 0 | Y30: 0 | Z30: 0 | AA30: 0 | AB30: 0 | AC30: 0 | AD30: 0 | AE30: 0 | AF30: 0 | AG30: 0
B31: ACC ACTUAL | C31: =C30 -> 0 | D31: =C31+D30 -> 0 | E31: =D31+E30 -> 0 | F31: =E31+F30 -> 90.3105 | G31: =F31+G30 -> 193.9455 | H31: =G31+H30 -> 284.256 | I31: =H31+I30 -> 284.256 | J31: =I31+J30 -> 284.256 | K31: =J31+K30 -> 387.891 | ... AG31: =AF31+AG30 -> 1100.0115 | AH31: =+AG31*1000 -> 1100011.5
B32: PLAN | C32: =$AK$90/31/1000 -> 4.6490908 | D32: =$AK$90/31/1000 -> 4.6490908 | E32: =$AK$90/31/1000 -> 4.6490908 | F32: =$AK$90/31/1000 -> 4.6490908 | G32: =$AK$90/31/1000 -> 4.6490908 | H32: =$AK$90/31/1000 -> 4.6490908 | I32: =$AK$90/31/1000 -> 4.6490908 | J32: =$AK$90/31/1000 -> 4.6490908 | ... AG32: =$AK$90/31/1000 -> 4.6490908
A33: TRT | B33: ACC PLAN | C33: =+C32 -> 4.6490908 | D33: =C33+D32 -> 9.2981817 | E33: =D33+E32 -> 13.947273 | F33: =E33+F32 -> 18.596363 | G33: =F33+G32 -> 23.245454 | H33: =G33+H32 -> 27.894545 | I33: =H33+I32 -> 32.543636 | J33: =I33+J32 -> 37.192727 | K33: =J33+K32 -> 41.841818 | ... AG33: =AF33+AG32 -> 144.12182
B34: ACTUAL | C34: 0 | D34: 0 | E34: 0 | F34: =5.953+19 -> 24.953 | G34: 0 | H34: 0 | I34: 0 | J34: 0 | K34: =4.5927+3.0697+35.91 -> 43.5724 | L34: 0 | M34: 0 | N34: 0 | O34: 0 | P34: 0 | Q34: 0 | R34: =2.77+0.23432+35.91+2.3328+2.9904 -> 44.23752 | S34: 0 | T34: 0 | U34: 0 | V34: 0 | W34: 0 | X34: 0 | Y34: =45.36+3.105+1.93464 -> 50.39964 | Z34: 0 | AA34: 0 | AB34: 0 | AC34: 0 | AD34: 0 | AE34: 0 | AF34: =9.3768+5.54+3.069+7.56+3.105 -> 28.6508 | AG34: 0 | AI34: ,
B35: ACC ACTUAL | C35: =C34 -> 0 | D35: =C35+D34 -> 0 | E35: =D35+E34 -> 0 | F35: =E35+F34 -> 24.953 | G35: =F35+G34 -> 24.953 | H35: =G35+H34 -> 24.953 | I35: =H35+I34 -> 24.953 | J35: =I35+J34 -> 24.953 | K35: =J35+K34 -> 68.5254 | ... AG35: =AF35+AG34 -> 191.81336 | AH35: =+AG35*1000 -> 191813.36
B36: PLAN | C36: =$AK$91/31/1000 -> 29.82871 | D36: =$AK$91/31/1000 -> 29.82871 | E36: =$AK$91/31/1000 -> 29.82871 | F36: =$AK$91/31/1000 -> 29.82871 | G36: =$AK$91/31/1000 -> 29.82871 | H36: =$AK$91/31/1000 -> 29.82871 | I36: =$AK$91/31/1000 -> 29.82871 | J36: =$AK$91/31/1000 -> 29.82871 | ... AG36: =$AK$91/31/1000 -> 29.82871
A37: FECL | B37: ACC PLAN | C37: =+C36 -> 29.82871 | D37: =C37+D36 -> 59.657419 | E37: =D37+E36 -> 89.486129 | F37: =E37+F36 -> 119.31484 | G37: =F37+G36 -> 149.14355 | H37: =G37+H36 -> 178.97226 | I37: =H37+I36 -> 208.80097 | J37: =I37+J36 -> 238.62968 | K37: =J37+K36 -> 268.45839 | ... AG37: =AF37+AG36 -> 924.69
B38: ACTUAL | C38: 0 | D38: 0 | E38: 0 | F38: =154.115 -> 154.115 | G38: 0 | H38: 0 | I38: 0 | J38: 0 | K38: =154.115 -> 154.115 | L38: 0 | M38: 0 | N38: =154.115 -> 154.115 | O38: 0 | P38: 0 | Q38: 0 | R38: =154.115 -> 154.115 | S38: 0 | T38: 0 | U38: 0 | V38: =154.115 -> 154.115 | W38: 0 | X38: 0 | Y38: 0 | Z38: =154.115 -> 154.115 | AA38: 0 | AB38: 0 | AC38: 0 | AD38: 0 | AE38: 0 | AF38: 0 | AG38: 0
B39: ACC ACTUAL | C39: =C38 -> 0 | D39: =C39+D38 -> 0 | E39: =D39+E38 -> 0 | F39: =E39+F38 -> 154.115 | G39: =F39+G38 -> 154.115 | H39: =G39+H38 -> 154.115 | I39: =H39+I38 -> 154.115 | J39: =I39+J38 -> 154.115 | K39: =J39+K38 -> 308.23 | ... AG39: =AF39+AG38 -> 924.69 | AH39: =+AG39*1000 -> 924690
B40: PLAN | C40: =$AK$95/31/1000 -> 112.63189 | D40: =$AK$95/31/1000 -> 112.63189 | E40: =$AK$95/31/1000 -> 112.63189 | F40: =$AK$95/31/1000 -> 112.63189 | G40: =$AK$95/31/1000 -> 112.63189 | H40: =$AK$95/31/1000 -> 112.63189 | I40: =$AK$95/31/1000 -> 112.63189 | J40: =$AK$95/31/1000 -> 112.63189 | ... AG40: =$AK$95/31/1000 -> 112.63189
A41: BELTON | B41: ACC PLAN | C41: =+C40 -> 112.63189 | D41: =C41+D40 -> 225.26378 | E41: =D41+E40 -> 337.89566 | F41: =E41+F40 -> 450.52755 | G41: =F41+G40 -> 563.15944 | H41: =G41+H40 -> 675.79133 | I41: =H41+I40 -> 788.42321 | J41: =I41+J40 -> 901.0551 | K41: =J41+K40 -> 1013.687 | ... AG41: =AF41+AG40 -> 3491.5885
B42: ACTUAL | C42: 0 | D42: 55.854 | E42: 0 | F42: 0 | G42: 0 | H42: 0 | I42: 0 | J42: 0 | K42: =481.73868+76.18464+83.781 -> 641.70432 | L42: 0 | M42: 167.56128 | N42: 0 | O42: 0 | P42: 0 | Q42: 0 | R42: =55.854+95.2308+481.73868 -> 632.82348 | S42: 0 | T42: 167.56128 | U42: 0 | V42: 0 | W42: 0 | X42: 0 | Y42: =95.2308+649.29996 -> 744.53076 | Z42: 0 | AA42: 0 | AB42: =76.18464+754.02576 -> 830.2104 | AC42: 0 | AD42: 0 | AE42: 0 | AF42: 0 | AG42: 0
...

Sheet Over view
O3: =+Data!A1 -> 46082

Sheet WD
P7: =+Data!A1 -> 46082
S50: Issued By | T50: Checked By | U50: Approve By

Sheet PRB
Q4: =+Data!A1 -> 46082
S50: Issued By | T50: Checked By | U50: Approve By

Sheet ADVICS
P3: =+Data!A1 -> 46082
S50: Issued By | T50: Checked By | U50: Approve By

Sheet TAP-C
P3: =+Data!A1 -> 46082
S50: Issued By | T50: Checked By | U50: Approve By

Sheet Other
P3: =+Data!A1 -> 46082
S44: Issued By | T44: Checked By | U44: Approve By

Sheet Sheet1
B2: Annual Sales
A3: Jan | B3: 70676806
A4: Feb | B4: 70546607
A5: Mar | B5: 68521227
A6: Apr | B6: 61903346 | D6: Sale Progres(%)
A7: May | B7: 77617486 | D7: Date | E7: 1 | F7: 2 | G7: 3 | H7: 4 | I7: 5 | J7: 6 | K7: 7 | L7: 8 | M7: 9 | N7: 10 | O7: 11 | P7: 12 | Q7: 13 | R7: 14 | S7: 15 | T7: 16 | U7: 17 | V7: 18 | W7: 19 | X7: 20 | Y7: 21 | Z7: 22 | AA7: 23 | AB7: 24 | AC7: 25 | AD7: 26 | AE7: 27 | AF7: 28 | AG7: 29 | AH7: 30 | AI7: 31
A8: Jun | B8: 76501452 | D8: SAP update
A9: Jul | B9: 73839707
A10: Aug | B10: 73870364
A11: Sep | B11: 74132422
A12: Oct | B12: 76751426
A13: Nov | B13: 74712370
A14: Dec | B14: 65967054
